Workbook

Sheet 사용안내
A1: 산업안전 RBF 사업 – 50개 기업 통합 사회비용 절감액 계산
A3: 시트 구성 | B3: 4종 시트 안내 | C3: ① 사용안내 ② 기준데이터(수정금지) ③ 기업별입력_[기업번호] ④ 전체통합집계
A4: Step 1 | B4: 기업 시트 선택 | C4: 하단 탭에서 '기업01' ~ '기업50' 탭 선택 → 해당 기업 입력 시작
A5: Step 2 | B5: 기업명·협력사명 입력 | C5: 각 기업 시트 상단 노란셀: 기업명, 협력사 수(최대5), 협력사1~5 이름 입력
A6: Step 3 | B6: 활동 횟수 입력 | C6: 노란색 입력셀에 활동 횟수 입력 (0=미이행, 1=1건, 2=2건, 3=3건 …)
A7: Step 4 | B7: 절감액 자동계산 | C7: 절감액 = 사회비용 × 가중치 × 활동횟수 → 자동 계산
A8: Step 5 | B8: 통합집계 확인 | C8: '전체통합집계' 시트에서 50개 기업 전체 합산 및 성과 판정 확인
A9: 주의① | B9: 위험도 확인 | C9: 별첨 제4조: 위험도(빈도×강도) 8점 이상 위험요인만 성과 인정
A10: 주의② | B10: 증빙서류 | C10: 표5(공학·관리적) / 표6(보호구) / 표7(교육) 기준 증빙 확인 후 입력
A11: 주의③ | B11: 기준데이터 시트 | C11: '기준데이터' 시트는 참조 전용 — 절대 수정 금지

Sheet 공급+수요기업
A1: 번호 | B1: 기업명 | C1: 사업자등록번호 (예시: 000-00-00000) | D1: 성명 | E1: 직책 | F1: 이메일 주소 | G1: 휴대폰 번호 (예시: 010-1234-5678) | H1: 부담당자 성명 | I1: 부담당자 직책 | J1: 부담당자 이메일 주소 | K1: 부담당자 휴대폰 번호 (예시: 010-1234-5678) | L1: 1차 사업비(백만원) | M1: 솔루션 | N1: 수요기업1 | O1: 수요기업2 | P1: 수요기업3 | Q1: 수요기업4 | R1: 수요기업5
A2: 기업 01 | B2: 강양HTS | C2: 354-87-00193 | D2: 홍승필 | E2: 차장 | F2: gangyanghts@naver.com | G2: 010-5432-6596 | H2: 안승일 | I2: 대표 | J2: gangyanghts@naver.com | K2: 010-4582-3908 | L2: 60 | M2: 공학
A3: 기업 02 | B3: 네오펜스 | C3: 502-87-02960 | D3: 이기철 | E3: 대표이사(연구책임자) | F3: neo@neofence.net | G3: 010-3203-7133 | L3: 70 | M3: 공학
A4: 기업 03 | B4: 라이브워크 | C4: 665-88-01764 | D4: 엄봉식 | E4: 대표이사 | F4: bliss21@livewalk.co.kr | G4: 010-9844-8321 | H4: 임민지 | I4: 차장 | J4: min123@livewalk.co.kr | K4: 010-5185-9627 | L4: 100 | M4: 공학
A5: 기업 04 | B5: 루미테크 | C5: 622-09-87246 | D5: 김명진 | E5: 대표 | F5: kmj4star@naver.com | G5: 010-5081-1843 | H5: 박영선 | I5: 실장 | J5: lumipark1004@naver.com | K5: 010-8233-1843 | L5: 80 | M5: 공학
A6: 기업 05 | B6: 리튬코리아 | C6: 397-87-02733 | D6: 김성준 | E6: 선임연구원 | F6: lk-korea@lkkor.com | G6: 010-3726-3142 | H6: 장성임 | I6: 실장 | J6: ion-korea@naver.com | K6: 010-5750-1029 | L6: 100 | M6: 공학
A7: 기업 06 | B7: 린솔 | C7: 766-87-02884 | D7: 도예영 | E7: 사원 | F7: yy1110@linsol.kr | G7: 010-3422-1444 | H7: 정다영 | I7: 대리 | J7: wjdekdud95@linsol.kr | K7: 010-7721-2274 | L7: 100 | M7: 공학
A8: 기업 07 | B8: 마이오티 | C8: 801-87-02718 | D8: 김상억 | E8: 부사장 | F8: rnbd@maiot.kr | G8: 010-2564-0744 | H8: 김탁규 | I8: 책임 | J8: tahkkyoo.kim@maiot.kr | K8: 010-9129-3325 | L8: 70 | M8: 공학
A9: 기업 08 | B9: 메이크순 | C9: 724-86-00468 | D9: 이항준 | E9: 원장 | F9: 011join001@hanmail.net | G9: 010-2308-2533 | H9: 김민재 | I9: 대리 | J9: makesoon@naver.com | K9: 010-8846-4705 | L9: 80 | M9: 공학
A10: 기업 09 | B10: 미리코 | C10: 134-81-79643 | D10: 김동현 | E10: 책임연구원(연구소소장) | F10: mirico@mirico.net | G10: 010-7715-1632 | H10: 박승현 | I10: 선임연구원 | J10: mirico@mirico.net | K10: 010-6364-0904 | L10: 70 | M10: 공학
A11: 기업 10 | B11: 베스트씨피알 | C11: 138-81-41310 | D11: 김은경 | E11: 부장 | F11: kimeg@aed.kr | G11: 010-5745-7777 | H11: 최지호 | I11: 부장 | J11: geo@aed.kr | K11: 010-8294-3075 | L11: 80 | M11: 공학
A12: 기업 11 | B12: 볼타온 | C12: 106-87-14633 | D12: 유신디(Yoo Cynthia Hyein) | E12: 이사 | F12: cyoo@voltaon.com | G12: 010-7232-5133 | H12: 홍용진 | I12: 상무 | J12: yjhong@voltaon.com | K12: 010-5319-7624 | L12: 70 | M12: 공학
A13: 기업 12 | B13: 브랜드뉴 | C13: 610-86-32701 | D13: 홍영정 | E13: 대리 | F13: hong.youngjung@brandnew-inc.com | G13: 010-3585-4341 | H13: 홍송헌 | I13: 과장 | J13: hong.songheon@brandnew-inc.com | K13: 010-3289-9595 | L13: 60 | M13: 공학
A14: 기업 13 | B14: 세계실업 | C14: 502-81-68126 | D14: 이정우 | E14: 과장 | F14: yolo807@worlde.co.kr | G14: 010-6774-3767 | H14: 고미숙 | I14: 이사 | J14: world5700@worlde.co.kr | K14: 010-8426-7424 | L14: 60 | M14: 공학
A15: 기업 14 | B15: 세르보테크 | C15: 263-87-02916 | D15: 김현진 | E15: 책임연구원 | F15: svtech23@naver.com | G15: 010-5486-9419 | L15: 60 | M15: 공학
A16: 기업 15 | B16: 신화테크 | C16: 138-81-69400 | D16: 설재호 | E16: 프로(선임연구원) | F16: lab2@shth.co.kr | G16: 010-2699-7336 | H16: 유정후 | I16: 책임 연구원 | J16: lab@shth.co.kr | K16: 메일로 연락 | L16: 80 | M16: 공학
A17: 기업 16 | B17: 아와소프트 | C17: 105-86-57078 | D17: 김양수 | E17: 이사 | F17: amadeuce@awasoft.co.kr | G17: 010-2720-0369 | H17: 이재관 | I17: 선임 | J17: jk.lee0207@awasoft.co.kr | K17: 010-5044-6839 | L17: 70 | M17: 공학
A18: 기업 17 | B18: 아임삭 | C18: 120-81-50894 | D18: 최문영 | E18: 주임 | F18: mychoi@aimsak.com | G18: 010-8030-4416 | H18: 김영삼 | I18: 부장 | J18: ys.kim@aimsak.com | K18: 010-9029-0760 | L18: 90 | M18: 공학
A19: 기업 18 | B19: 에이엘테크 | C19: 503-81-46125 | D19: 구나리 | E19: 선임연구원 | F19: nrkoo@al-tech.kr | G19: 010-7762-4753 | H19: 김희진 | I19: 수석연구원 | J19: dkim@al-tech.kr | K19: 010-7508-5503 | L19: 80 | M19: 공학
A20: 기업 19 | B20: 예스산업시스템 | C20: 305-81-99784 | D20: 김지은 | E20: 차장 | F20: yes5756@daum.net | G20: 010-7280-0316 | H20: 이진숙 | I20: 과장 | J20: yes5756@daum.net | K20: 010-2322-3066 | L20: 60 | M20: 공학
A21: 기업 20 | B21: 오메가오토메이션 | C21: 722-86-00292 | D21: 양경식 | E21: 실장 | F21: ps@omegaautomation.co.kr | G21: 010-2223-8296 | H21: 김유한 | I21: 사원 | J21: ps@omegaautomation.co.kr | K21: 010-8306-5305 | L21: 70 | M21: 공학
A22: 기업 21 | B22: 이노넷 | C22: 129-86-56468 | D22: 성봉희 | E22: 경영지원팀장 | F22: admin@innonet.net | G22: 010-2714-3804 | H22: 장혜원 | I22: 경영지원팀 매니저 | J22: admin@innonet.net | K22: 010-5668-8187 | L22: 80 | M22: 공학
A23: 기업 22 | B23: 인제컴퍼니 | C23: 673-01-02119 | D23: 이정율 | E23: 대표 | F23: inje3482@naver.com | G23: 010-9695-8238 | H23: 홍미지 | I23: 대리 | J23: inje3482@naver.com | K23: 010-6537-0758 | L23: 70 | M23: 공학
A24: 기업 23 | B24: 인포카 | C24: 110-88-00402 | D24: 곽지선 | E24: 경영지원팀 팀장 | F24: rnd@infocarmobility.com | G24: 010-3108-8926 | H24: 황근중 | I24: 영업팀 팀장 | J24: market@infocarmobility.com | K24: 010-6698-6940 | L24: 70 | M24: 공학
A25: 기업 24 | B25: 정한스틸 | C25: 312-86-39867 | D25: 한금수 | E25: 대표이사 | F25: jhst1217@daum.net | G25: 010-9393-9346 | H25: 한동우 | I25: 대리 | J25: jhst1217@daum.net | K25: 010-2516-9346 | L25: 60 | M25: 공학
A26: 기업 25 | B26: 지노시스 | C26: 314-86-31783 | D26: 오장진 | E26: 부장 | F26: jinosys@naver.com | G26: 010-9688-0512 | H26: 박영진 | I26: 대표이사 | J26: pyjpark@nate.com | K26: 010-4452-4492 | L26: 60 | M26: 공학
A27: 기업 26 | B27: 지우테크 | C27: 129-81-31064 | D27: 방준호 | E27: 대리 | F27: jhbang@jiwootech.kr | G27: 010-5920-8536 | H27: 최진수 | I27: 부장 | J27: zschoi@jiwootech.kr | K27: 010-7777-4684 | L27: 100 | M27: 공학
... A36: 기업 35 | B36: 해동실업 | C36: 306-87-02381 | D36: 조성철 | E36: 대표 | F36: hd7274@naver.com | G36: 010-8505-5383 | H36: 김오영 | I36: 부장 | J36: hd7274@naver.com | K36: 010-2869-1850 | L36: 80 | M36: 공학
A37: 기업 36 | B37: 휴먼디펜스 | C37: 495-86-02516 | D37: 이재환 | E37: 대표이사 | F37: human-defence@naver.com | G37: 010-6303-8684 | L37: 70 | M37: 공학
A38: 기업 37 | B38: 무브엔 | C38: 267-81-00219 | D38: 박찬희 | E38: 과장 | F38: roypark3@muveen.com | G38: 010-7675-9100 | H38: 백준협 | I38: 이사 | J38: joonbaek@muveen.com | K38: 010-3728-1310 | L38: 50 | M38: 보호구
A39: 기업 38 | B39: 비앤알 | C39: 131-81-78500 | D39: 김훈희 | E39: 팀장 | F39: hoony220@vaxcon.com | G39: 010-8817-2256 | H39: 이태경 | I39: 팀장 | J39: LeeT@vaxcon.com | K39: 010-4119-1272 | L39: 50 | M39: 보호구
A40: 기업 39 | B40: 세이프웨어 | C40: 587-81-00466 | D40: 김영환 | E40: 실장 | F40: brian@safeware.co.kr | G40: 010-3010-0375 | L40: 50 | M40: 보호구
A41: 기업 40 | B41: 에네스 | C41: 448-88-01169 | D41: 정재진 | E41: 대표이사 | F41: dnflsksna@naver.com | G41: 010-7749-5986 | H41: 이길호 | I41: 전무이사 | J41: matrix307@naver.com | K41: 010-5511-6121 | L41: 60 | M41: 보호구 | T41: 문경균 | U41: 팀장 | V41: ansxod1339@naver.com | W41: 010-4045-2855
A42: 기업 41 | B42: 에이치에이치에스 | C42: 545-86-00259 | D42: 김정욱 | E42: 전임 | F42: hhskorea2016@gmail.com | G42: 010-6676-9913 | H42: 김정욱 | I42: 전임 | J42: jungwook312662@naver.com | K42: 010-6676-9913 | L42: 60 | M42: 보호구
A43: 기업 42 | B43: 에일리언테크놀로지아시아 | C43: 131-86-00327 | D43: 한승식 | E43: 부장 | F43: rubyon@alienasia.com | G43: 010-6261-9801 | H43: 박정은 | I43: 부장 | J43: jepark@alienasia.com | K43: 010-2788-3927 | L43: 40 | M43: 보호구
A44: 기업 43 | B44: 유니드 | C44: 613-81-61025 | D44: 허석형 | E44: 과장 | F44: hsh6055@unids.kr | G44: 010-6585-6055 | H44: 강미리 | I44: 과장 | J44: kkang7165@unids.kr | K44: 010-5375-4128 | L44: 50 | M44: 보호구
A45: 기업 44 | B45: 대한건설구조안전 | C45: 301-87-02858 | D45: 유승우 | E45: 차장 | F45: sw.yoo@ikcss.co.kr | G45: 010-3743-8745 | H45: 정기훈 | I45: 과장 | J45: gh.jeong@ikcss.co.kr | K45: 010-8323-9949 | L45: 30 | M45: 행동교정
A46: 기업 45 | B46: 대한안전보건교육원 | C46: 513-86-02814 | D46: 이범석 | E46: 부대표 | F46: edu@kesh.co.kr | G46: 010-9361-3944 | H46: 안유현 | I46: 팀장 | J46: edu@kesh.co.kr | K46: 010-2544-9652 | L46: 30 | M46: 행동교정
A47: 기업 46 | B47: 드림캠퍼스 | C47: 457-81-00976 | D47: 서재홍 | E47: 대표이사 | F47: miz@dreamcampus.co.kr | G47: 010-7556-3721 | H47: 박명선 | I47: 실장 | J47: supergirl35@dreamcampus.co.kr | K47: 010-3919-0035 | L47: 30 | M47: 행동교정
A48: 기업 47 | B48: 엠라인스튜디오 | C48: 211-88-85418 | D48: 이재호 | E48: 책임 | F48: jaylee@m-line.tv | G48: 010-2992-6595 | L48: 40 | M48: 행동교정
...

Sheet 전체통합집계
A1: 산업안전 RBF 사업 – 50개 기업 통합 집계표
A2: ※ 각 기업 시트의 입력값을 자동 집계합니다. 이 시트는 수정하지 마십시오.
J3: 활동별 사회비용(원) | L3: 총 사회비용(원) | BB3: 금액
A4: 사업 구분 | B4: 1차 사업 | D4: '1차 사업' 또는 '2차 사업' 입력 → 투입금액·성과기준 자동 반영 | I4: 공학·관리적 조치 | J4: =BB4 -> 1.0088468e+10 | L4: =J4+J5+J6 -> 1.0895524e+10 | BA4: 공학·관리적 조치 | BB4: =SUM(BB8,BB11,BB14,BB17,BB20,BB23,BB26,BB29,BB32,BB35,BB38,BB41,BB44) -> 1.0088468e+10
A5: 투입금액(원) | B5: =IF(B4="1차 사업",3300000000,IF(B4="2차 사업",3200000000,"")) -> 3300000000 | D5: 성과 미달 기준(이하) | E5: =IF(B4="1차 사업",3500000000,IF(B4="2차 사업",3300000000,"")) -> 3500000000 | F5: 최대 성과목표(이상) | G5: =IF(B4="1차 사업",6600000000,IF(B4="2차 사업",6400000000,"")) -> 6600000000 | I5: 개인보호구 지급 | J5: =BB5 -> 3.2399154e+08 | BA5: 개인보호구 지급 | BB5: =SUM(BB9,BB12,BB15,BB18,BB21,BB24,BB27,BB30,BB33,BB36,BB39,BB42,BB45) -> 3.2399154e+08
I6: 행동 교정(교육) | J6: =BB6 -> 4.8306397e+08 | BA6: 행동 교정(교육) | BB6: =SUM(BB10,BB13,BB16,BB19,BB22,BB25,BB28,BB31,BB34,BB37,BB40,BB43,BB46) -> 4.8306397e+08
A7: No | B7: 기업명 | D7: =기업01!B4 -> 기업 01 | E7: =기업02!B4 -> 기업 02 | F7: =기업03!B4 -> 기업 03 | G7: =기업04!B4 -> 기업 04 | H7: =기업05!B4 -> 기업 05 | I7: =기업06!B4 -> 기업 06 | J7: =기업07!B4 -> 기업 07 | K7: =기업08!B4 -> 기업 08 | L7: =기업09!B4 -> 기업 09 | M7: =기업10!B4 -> 기업 10 | N7: =기업11!B4 -> 기업 11 | O7: =기업12!B4 -> 기업 12 | P7: =기업13!B4 -> 기업 13 | Q7: =기업14!B4 -> 기업 14 | R7: =기업15!B4 -> 기업 15 | S7: =기업16!B4 -> 기업 16 | T7: =기업17!B4 -> 기업 17 | U7: =기업18!B4 -> 기업 18 | V7: =기업19!B4 -> 기업 19 | W7: =기업20!B4 -> 기업 20 | X7: =기업21!B4 -> 기업 21 | Y7: =기업22!B4 -> 기업 22 | Z7: =기업23!B4 -> 기업 23 | AA7: =기업24!B4 -> 기업 24 | AB7: =기업25!B4 -> 기업 25 | AC7: =기업26!B4 -> 기업 26 | AD7: =기업27!B4 -> 기업 27 | AE7: =기업28!B4 -> 기업 28 | AF7: =기업29!B4 -> 기업 29 | AG7: =기업30!B4 -> 기업 30 | AH7: =기업31!B4 -> 기업 31 | AI7: =기업32!B4 -> 기업 32 | AJ7: =기업33!B4 -> 기업 33 | AK7: =기업34!B4 -> 기업 34 | AL7: =기업35!B4 -> 기업 35 | AM7: =기업36!B4 -> 기업 36 | AN7: =기업37!B4 -> 기업 37 | AO7: =기업38!B4 -> 기업 38 | AP7: =기업39!B4 -> 기업 39 | AQ7: =기업40!B4 -> 기업 40 | AR7: =기업41!B4 -> 기업 41 | AS7: =기업42!B4 -> 기업 42 | AT7: =기업43!B4 -> 기업 43 | AU7: =기업44!B4 -> 기업 44 | AV7: =기업45!B4 -> 기업 45 | AW7: =기업46!B4 -> 기업 46 | AX7: =기업47!B4 -> 기업 47 | AY7: =기업48!B4 -> 기업 48 | AZ7: =기업49!B4 -> 기업 49 | BA7: =기업50!B4 -> 기업 50 | BB7: 전체 합계
A8: 1 | B8: 떨어짐 | C8: 공학·관리적 조치 | D8: =기업01!L10 -> 2.0841404e+08 | E8: =기업02!L10 -> 2.0841404e+08 | F8: =기업03!L10 -> 2.0841404e+08 | G8: =기업04!L10 -> 2.0841404e+08 | H8: =기업05!L10 -> 2.0841404e+08 | I8: =기업06!L10 -> 2.0841404e+08 | J8: =기업07!L10 -> 2.0841404e+08 | K8: =기업08!L10 -> 2.0841404e+08 | L8: =기업09!L10 -> 2.0841404e+08 | M8: =기업10!L10 -> 2.0841404e+08 | N8: =기업11!L10 -> 2.0841404e+08 | O8: =기업12!L10 -> 2.0841404e+08 | P8: =기업13!L10 -> 0 | Q8: =기업14!L10 -> 0 | R8: =기업15!L10 -> 0 | S8: =기업16!L10 -> 0 | T8: =기업17!L10 -> 0 | U8: =기업18!L10 -> 0 | V8: =기업19!L10 -> 0 | W8: =기업20!L10 -> 0 | X8: =기업21!L10 -> 0 | Y8: =기업22!L10 -> 0 | Z8: =기업23!L10 -> 0 | AA8: =기업24!L10 -> 0 | AB8: =기업25!L10 -> 0 | AC8: =기업26!L10 -> 0 | AD8: =기업27!L10 -> 0 | AE8: =기업28!L10 -> 0 | AF8: =기업29!L10 -> 0 | AG8: =기업30!L10 -> 0 | AH8: =기업31!L10 -> 0 | AI8: =기업32!L10 -> 0 | AJ8: =기업33!L10 -> 0 | AK8: =기업34!L10 -> 0 | AL8: =기업35!L10 -> 0 | AM8: =기업36!L10 -> 0 | AN8: =기업37!L10 -> 0 | AO8: =기업38!L10 -> 0 | AP8: =기업39!L10 -> 0 | AQ8: =기업40!L10 -> 0 | AR8: =기업41!L10 -> 0 | AS8: =기업42!L10 -> 0 | AT8: =기업43!L10 -> 0 | AU8: =기업44!L10 -> 0 | AV8: =기업45!L10 -> 0 | AW8: =기업46!L10 -> 0 | AX8: =기업47!L10 -> 0 | AY8: =기업48!L10 -> 0 | AZ8: =기업49!L10 -> 0 | BA8: =기업50!L10 -> 0 | BB8: =D8+E8+F8+G8+H8+I8+J8+K8+L8+M8+N8+O8+P8+Q8+R8+S8+T8+U8+V8+W8+X8+Y8+Z8+AA8+AB8+AC8+AD8+AE8+AF8+AG8+AH8+AI8+AJ8+AK8+AL8+AM8+AN8+AO8+AP8+AQ8+AR8+AS8+AT8+AU8+AV8+AW8+AX8+AY8+AZ8+BA8 -> 2.5009685e+09
C9: 개인보호구 지급 | D9: =기업01!L11 -> 5582519 | E9: =기업02!L11 -> 0 | F9: =기업03!L11 -> 0 | G9: =기업04!L11 -> 0 | H9: =기업05!L11 -> 0 | I9: =기업06!L11 -> 0 | J9: =기업07!L11 -> 0 | K9: =기업08!L11 -> 0 | L9: =기업09!L11 -> 0 | M9: =기업10!L11 -> 0 | N9: =기업11!L11 -> 0 | O9: =기업12!L11 -> 0 | P9: =기업13!L11 -> 0 | Q9: =기업14!L11 -> 0 | R9: =기업15!L11 -> 0 | S9: =기업16!L11 -> 0 | T9: =기업17!L11 -> 0 | U9: =기업18!L11 -> 0 | V9: =기업19!L11 -> 0 | W9: =기업20!L11 -> 0 | X9: =기업21!L11 -> 0 | Y9: =기업22!L11 -> 0 | Z9: =기업23!L11 -> 0 | AA9: =기업24!L11 -> 0 | AB9: =기업25!L11 -> 0 | AC9: =기업26!L11 -> 0 | AD9: =기업27!L11 -> 0 | AE9: =기업28!L11 -> 0 | AF9: =기업29!L11 -> 0 | AG9: =기업30!L11 -> 0 | AH9: =기업31!L11 -> 0 | AI9: =기업32!L11 -> 0 | AJ9: =기업33!L11 -> 0 | AK9: =기업34!L11 -> 0 | AL9: =기업35!L11 -> 0 | AM9: =기업36!L11 -> 0 | AN9: =기업37!L11 -> 16747557 | AO9: =기업38!L11 -> 16747557 | AP9: =기업39!L11 -> 16747557 | AQ9: =기업40!L11 -> 16747557 | AR9: =기업41!L11 -> 16747557 | AS9: =기업42!L11 -> 16747557 | AT9: =기업43!L11 -> 16747557 | AU9: =기업44!L11 -> 0 | AV9: =기업45!L11 -> 0 | AW9: =기업46!L11 -> 0 | AX9: =기업47!L11 -> 0 | AY9: =기업48!L11 -> 0 | AZ9: =기업49!L11 -> 0 | BA9: =기업50!L11 -> 0 | BB9: =D9+E9+F9+G9+H9+I9+J9+K9+L9+M9+N9+O9+P9+Q9+R9+S9+T9+U9+V9+W9+X9+Y9+Z9+AA9+AB9+AC9+AD9+AE9+AF9+AG9+AH9+AI9+AJ9+AK9+AL9+AM9+AN9+AO9+AP9+AQ9+AR9+AS9+AT9+AU9+AV9+AW9+AX9+AY9+AZ9+BA9 -> 1.2281542e+08
C10: 행동 교정(교육) | D10: =기업01!L12 -> 0 | E10: =기업02!L12 -> 0 | F10: =기업03!L12 -> 0 | G10: =기업04!L12 -> 0 | H10: =기업05!L12 -> 0 | I10: =기업06!L12 -> 0 | J10: =기업07!L12 -> 0 | K10: =기업08!L12 -> 0 | L10: =기업09!L12 -> 0 | M10: =기업10!L12 -> 0 | N10: =기업11!L12 -> 0 | O10: =기업12!L12 -> 0 | P10: =기업13!L12 -> 0 | Q10: =기업14!L12 -> 0 | R10: =기업15!L12 -> 0 | S10: =기업16!L12 -> 0 | T10: =기업17!L12 -> 0 | U10: =기업18!L12 -> 0 | V10: =기업19!L12 -> 0 | W10: =기업20!L12 -> 0 | X10: =기업21!L12 -> 0 | Y10: =기업22!L12 -> 0 | Z10: =기업23!L12 -> 0 | AA10: =기업24!L12 -> 0 | AB10: =기업25!L12 -> 0 | AC10: =기업26!L12 -> 0 | AD10: =기업27!L12 -> 0 | AE10: =기업28!L12 -> 0 | AF10: =기업29!L12 -> 0 | AG10: =기업30!L12 -> 0 | AH10: =기업31!L12 -> 0 | AI10: =기업32!L12 -> 0 | AJ10: =기업33!L12 -> 0 | AK10: =기업34!L12 -> 0 | AL10: =기업35!L12 -> 0 | AM10: =기업36!L12 -> 0 | AN10: =기업37!L12 -> 0 | AO10: =기업38!L12 -> 0 | AP10: =기업39!L12 -> 0 | AQ10: =기업40!L12 -> 0 | AR10: =기업41!L12 -> 0 | AS10: =기업42!L12 -> 0 | AT10: =기업43!L12 -> 0 | AU10: =기업44!L12 -> 5582519 | AV10: =기업45!L12 -> 5582519 | AW10: =기업46!L12 -> 5582519 | AX10: =기업47!L12 -> 5582519 | AY10: =기업48!L12 -> 5582519 | AZ10: =기업49!L12 -> 5582519 | BA10: =기업50!L12 -> 0 | BB10: =D10+E10+F10+G10+H10+I10+J10+K10+L10+M10+N10+O10+P10+Q10+R10+S10+T10+U10+V10+W10+X10+Y10+Z10+AA10+AB10+AC10+AD10+AE10+AF10+AG10+AH10+AI10+AJ10+AK10+AL10+AM10+AN10+AO10+AP10+AQ10+AR10+AS10+AT10+AU10+AV10+AW10+AX10+AY10+AZ10+BA10 -> 33495114
A11: 2 | B11: 넘어짐 | C11: 공학·관리적 조치 | D11: =기업01!L13 -> 0 | E11: =기업02!L13 -> 0 | F11: =기업03!L13 -> 0 | G11: =기업04!L13 -> 0 | H11: =기업05!L13 -> 0 | I11: =기업06!L13 -> 0 | J11: =기업07!L13 -> 0 | K11: =기업08!L13 -> 0 | L11: =기업09!L13 -> 0 | M11: =기업10!L13 -> 0 | N11: =기업11!L13 -> 0 | O11: =기업12!L13 -> 0 | P11: =기업13!L13 -> 0 | Q11: =기업14!L13 -> 0 | R11: =기업15!L13 -> 0 | S11: =기업16!L13 -> 0 | T11: =기업17!L13 -> 0 | U11: =기업18!L13 -> 0 | V11: =기업19!L13 -> 0 | W11: =기업20!L13 -> 0 | X11: =기업21!L13 -> 0 | Y11: =기업22!L13 -> 0 | Z11: =기업23!L13 -> 0 | AA11: =기업24!L13 -> 0 | AB11: =기업25!L13 -> 0 | AC11: =기업26!L13 -> 0 | AD11: =기업27!L13 -> 0 | AE11: =기업28!L13 -> 0 | AF11: =기업29!L13 -> 0 | AG11: =기업30!L13 -> 0 | AH11: =기업31!L13 -> 0 | AI11: =기업32!L13 -> 0 | AJ11: =기업33!L13 -> 0 | AK11: =기업34!L13 -> 0 | AL11: =기업35!L13 -> 0 | AM11: =기업36!L13 -> 0 | AN11: =기업37!L13 -> 0 | AO11: =기업38!L13 -> 0 | AP11: =기업39!L13 -> 0 | AQ11: =기업40!L13 -> 0 | AR11: =기업41!L13 -> 0 | AS11: =기업42!L13 -> 0 | AT11: =기업43!L13 -> 0 | AU11: =기업44!L13 -> 0 | AV11: =기업45!L13 -> 0 | AW11: =기업46!L13 -> 0 | AX11: =기업47!L13 -> 0 | AY11: =기업48!L13 -> 0 | AZ11: =기업49!L13 -> 0 | BA11: =기업50!L13 -> 0 | BB11: =D11+E11+F11+G11+H11+I11+J11+K11+L11+M11+N11+O11+P11+Q11+R11+S11+T11+U11+V11+W11+X11+Y11+Z11+AA11+AB11+AC11+AD11+AE11+AF11+AG11+AH11+AI11+AJ11+AK11+AL11+AM11+AN11+AO11+AP11+AQ11+AR11+AS11+AT11+AU11+AV11+AW11+AX11+AY11+AZ11+BA11 -> 0
C12: 개인보호구 지급 | D12: =기업01!L14 -> 0 | E12: =기업02!L14 -> 0 | F12: =기업03!L14 -> 0 | G12: =기업04!L14 -> 0 | H12: =기업05!L14 -> 0 | I12: =기업06!L14 -> 0 | J12: =기업07!L14 -> 0 | K12: =기업08!L14 -> 0 | L12: =기업09!L14 -> 0 | M12: =기업10!L14 -> 0 | N12: =기업11!L14 -> 0 | O12: =기업12!L14 -> 0 | P12: =기업13!L14 -> 0 | Q12: =기업14!L14 -> 0 | R12: =기업15!L14 -> 0 | S12: =기업16!L14 -> 0 | T12: =기업17!L14 -> 0 | U12: =기업18!L14 -> 0 | V12: =기업19!L14 -> 0 | W12: =기업20!L14 -> 0 | X12: =기업21!L14 -> 0 | Y12: =기업22!L14 -> 0 | Z12: =기업23!L14 -> 0 | AA12: =기업24!L14 -> 0 | AB12: =기업25!L14 -> 0 | AC12: =기업26!L14 -> 0 | AD12: =기업27!L14 -> 0 | AE12: =기업28!L14 -> 0 | AF12: =기업29!L14 -> 0 | AG12: =기업30!L14 -> 0 | AH12: =기업31!L14 -> 0 | AI12: =기업32!L14 -> 0 | AJ12: =기업33!L14 -> 0 | AK12: =기업34!L14 -> 0 | AL12: =기업35!L14 -> 0 | AM12: =기업36!L14 -> 0 | AN12: =기업37!L14 -> 2008108.6 | AO12: =기업38!L14 -> 2008108.6 | AP12: =기업39!L14 -> 2008108.6 | AQ12: =기업40!L14 -> 2008108.6 | AR12: =기업41!L14 -> 2008108.6 | AS12: =기업42!L14 -> 2008108.6 | AT12: =기업43!L14 -> 2008108.6 | AU12: =기업44!L14 -> 0 | AV12: =기업45!L14 -> 0 | AW12: =기업46!L14 -> 0 | AX12: =기업47!L14 -> 0 | AY12: =기업48!L14 -> 0 | AZ12: =기업49!L14 -> 0 | BA12: =기업50!L14 -> 0 | BB12: =D12+E12+F12+G12+H12+I12+J12+K12+L12+M12+N12+O12+P12+Q12+R12+S12+T12+U12+V12+W12+X12+Y12+Z12+AA12+AB12+AC12+AD12+AE12+AF12+AG12+AH12+AI12+AJ12+AK12+AL12+AM12+AN12+AO12+AP12+AQ12+AR12+AS12+AT12+AU12+AV12+AW12+AX12+AY12+AZ12+BA12 -> 14056761
C13: 행동 교정(교육) | D13: =기업01!L15 -> 0 | E13: =기업02!L15 -> 0 | F13: =기업03!L15 -> 0 | G13: =기업04!L15 -> 0 | H13: =기업05!L15 -> 0 | I13: =기업06!L15 -> 0 | J13: =기업07!L15 -> 0 | K13: =기업08!L15 -> 0 | L13: =기업09!L15 -> 0 | M13: =기업10!L15 -> 0 | N13: =기업11!L15 -> 0 | O13: =기업12!L15 -> 0 | P13: =기업13!L15 -> 0 | Q13: =기업14!L15 -> 0 | R13: =기업15!L15 -> 0 | S13: =기업16!L15 -> 0 | T13: =기업17!L15 -> 0 | U13: =기업18!L15 -> 0 | V13: =기업19!L15 -> 0 | W13: =기업20!L15 -> 0 | X13: =기업21!L15 -> 0 | Y13: =기업22!L15 -> 0 | Z13: =기업23!L15 -> 0 | AA13: =기업24!L15 -> 0 | AB13: =기업25!L15 -> 0 | AC13: =기업26!L15 -> 0 | AD13: =기업27!L15 -> 0 | AE13: =기업28!L15 -> 0 | AF13: =기업29!L15 -> 0 | AG13: =기업30!L15 -> 0 | AH13: =기업31!L15 -> 0 | AI13: =기업32!L15 -> 0 | AJ13: =기업33!L15 -> 0 | AK13: =기업34!L15 -> 0 | AL13: =기업35!L15 -> 0 | AM13: =기업36!L15 -> 0 | AN13: =기업37!L15 -> 2008108.6 | AO13: =기업38!L15 -> 0 | AP13: =기업39!L15 -> 0 | AQ13: =기업40!L15 -> 0 | AR13: =기업41!L15 -> 0 | AS13: =기업42!L15 -> 0 | AT13: =기업43!L15 -> 0 | AU13: =기업44!L15 -> 2008108.6 | AV13: =기업45!L15 -> 4016217.3 | AW13: =기업46!L15 -> 4016217.3 | AX13: =기업47!L15 -> 4016217.3 | AY13: =기업48!L15 -> 4016217.3 | AZ13: =기업49!L15 -> 4016217.3 | BA13: =기업50!L15 -> 2008108.6 | BB13: =D13+E13+F13+G13+H13+I13+J13+K13+L13+M13+N13+O13+P13+Q13+R13+S13+T13+U13+V13+W13+X13+Y13+Z13+AA13+AB13+AC13+AD13+AE13+AF13+AG13+AH13+AI13+AJ13+AK13+AL13+AM13+AN13+AO13+AP13+AQ13+AR13+AS13+AT13+AU13+AV13+AW13+AX13+AY13+AZ13+BA13 -> 26105412
A14: 3 | B14: 깔림·뒤집힘 | C14: 공학·관리적 조치 | D14: =기업01!L16 -> 0 | E14: =기업02!L16 -> 24964659 | F14: =기업03!L16 -> 24964659 | G14: =기업04!L16 -> 24964659 | H14: =기업05!L16 -> 24964659 | I14: =기업06!L16 -> 24964659 | J14: =기업07!L16 -> 24964659 | K14: =기업08!L16 -> 24964659 | L14: =기업09!L16 -> 24964659 | M14: =기업10!L16 -> 24964659 | N14: =기업11!L16 -> 24964659 | O14: =기업12!L16 -> 24964659 | P14: =기업13!L16 -> 0 | Q14: =기업14!L16 -> 0 | R14: =기업15!L16 -> 0 | S14: =기업16!L16 -> 0 | T14: =기업17!L16 -> 0 | U14: =기업18!L16 -> 0 | V14: =기업19!L16 -> 0 | W14: =기업20!L16 -> 0 | X14: =기업21!L16 -> 0 | Y14: =기업22!L16 -> 0 | Z14: =기업23!L16 -> 0 | AA14: =기업24!L16 -> 0 | AB14: =기업25!L16 -> 0 | AC14: =기업26!L16 -> 0 | AD14: =기업27!L16 -> 0 | AE14: =기업28!L16 -> 0 | AF14: =기업29!L16 -> 0 | AG14: =기업30!L16 -> 0 | AH14: =기업31!L16 -> 0 | AI14: =기업32!L16 -> 0 | AJ14: =기업33!L16 -> 0 | AK14: =기업34!L16 -> 0 | AL14: =기업35!L16 -> 0 | AM14: =기업36!L16 -> 0 | AN14: =기업37!L16 -> 0 | AO14: =기업38!L16 -> 0 | AP14: =기업39!L16 -> 0 | AQ14: =기업40!L16 -> 0 | AR14: =기업41!L16 -> 0 | AS14: =기업42!L16 -> 0 | AT14: =기업43!L16 -> 0 | AU14: =기업44!L16 -> 0 | AV14: =기업45!L16 -> 0 | AW14: =기업46!L16 -> 0 | AX14: =기업47!L16 -> 0 | AY14: =기업48!L16 -> 0 | AZ14: =기업49!L16 -> 0 | BA14: =기업50!L16 -> 0 | BB14: =D14+E14+F14+G14+H14+I14+J14+K14+L14+M14+N14+O14+P14+Q14+R14+S14+T14+U14+V14+W14+X14+Y14+Z14+AA14+AB14+AC14+AD14+AE14+AF14+AG14+AH14+AI14+AJ14+AK14+AL14+AM14+AN14+AO14+AP14+AQ14+AR14+AS14+AT14+AU14+AV14+AW14+AX14+AY14+AZ14+BA14 -> 2.7461124e+08
C15: 개인보호구 지급 | D15: =기업01!L17 -> 0 | E15: =기업02!L17 -> 0 | F15: =기업03!L17 -> 0 | G15: =기업04!L17 -> 0 | H15: =기업05!L17 -> 0 | I15: =기업06!L17 -> 0 | J15: =기업07!L17 -> 0 | K15: =기업08!L17 -> 0 | L15: =기업09!L17 -> 0 | M15: =기업10!L17 -> 0 | N15: =기업11!L17 -> 0 | O15: =기업12!L17 -> 0 | P15: =기업13!L17 -> 0 | Q15: =기업14!L17 -> 0 | R15: =기업15!L17 -> 0 | S15: =기업16!L17 -> 0 | T15: =기업17!L17 -> 0 | U15: =기업18!L17 -> 0 | V15: =기업19!L17 -> 0 | W15: =기업20!L17 -> 0 | X15: =기업21!L17 -> 0 | Y15: =기업22!L17 -> 0 | Z15: =기업23!L17 -> 0 | AA15: =기업24!L17 -> 0 | AB15: =기업25!L17 -> 0 | AC15: =기업26!L17 -> 0 | AD15: =기업27!L17 -> 0 | AE15: =기업28!L17 -> 0 | AF15: =기업29!L17 -> 0 | AG15: =기업30!L17 -> 0 | AH15: =기업31!L17 -> 0 | AI15: =기업32!L17 -> 0 | AJ15: =기업33!L17 -> 0 | AK15: =기업34!L17 -> 0 | AL15: =기업35!L17 -> 0 | AM15: =기업36!L17 -> 0 | AN15: =기업37!L17 -> 5349569.7 | AO15: =기업38!L17 -> 5349569.7 | AP15: =기업39!L17 -> 5349569.7 | AQ15: =기업40!L17 -> 5349569.7 | AR15: =기업41!L17 -> 5349569.7 | AS15: =기업42!L17 -> 5349569.7 | AT15: =기업43!L17 -> 5349569.7 | AU15: =기업44!L17 -> 0 | AV15: =기업45!L17 -> 0 | AW15: =기업46!L17 -> 0 | AX15: =기업47!L17 -> 0 | AY15: =기업48!L17 -> 0 | AZ15: =기업49!L17 -> 0 | BA15: =기업50!L17 -> 0 | BB15: =D15+E15+F15+G15+H15+I15+J15+K15+L15+M15+N15+O15+P15+Q15+R15+S15+T15+U15+V15+W15+X15+Y15+Z15+AA15+AB15+AC15+AD15+AE15+AF15+AG15+AH15+AI15+AJ15+AK15+AL15+AM15+AN15+AO15+AP15+AQ15+AR15+AS15+AT15+AU15+AV15+AW15+AX15+AY15+AZ15+BA15 -> 37446988
C16: 행동 교정(교육) | D16: =기업01!L18 -> 0 | E16: =기업02!L18 -> 0 | F16: =기업03!L18 -> 0 | G16: =기업04!L18 -> 0 | H16: =기업05!L18 -> 0 | I16: =기업06!L18 -> 0 | J16: =기업07!L18 -> 0 | K16: =기업08!L18 -> 0 | L16: =기업09!L18 -> 0 | M16: =기업10!L18 -> 0 | N16: =기업11!L18 -> 0 | O16: =기업12!L18 -> 0 | P16: =기업13!L18 -> 0 | Q16: =기업14!L18 -> 0 | R16: =기업15!L18 -> 0 | S16: =기업16!L18 -> 0 | T16: =기업17!L18 -> 0 | U16: =기업18!L18 -> 0 | V16: =기업19!L18 -> 0 | W16: =기업20!L18 -> 0 | X16: =기업21!L18 -> 0 | Y16: =기업22!L18 -> 0 | Z16: =기업23!L18 -> 0 | AA16: =기업24!L18 -> 0 | AB16: =기업25!L18 -> 0 | AC16: =기업26!L18 -> 0 | AD16: =기업27!L18 -> 0 | AE16: =기업28!L18 -> 0 | AF16: =기업29!L18 -> 0 | AG16: =기업30!L18 -> 0 | AH16: =기업31!L18 -> 0 | AI16: =기업32!L18 -> 0 | AJ16: =기업33!L18 -> 0 | AK16: =기업34!L18 -> 0 | AL16: =기업35!L18 -> 0 | AM16: =기업36!L18 -> 0 | AN16: =기업37!L18 -> 0 | AO16: =기업38!L18 -> 0 | AP16: =기업39!L18 -> 0 | AQ16: =기업40!L18 -> 0 | AR16: =기업41!L18 -> 0 | AS16: =기업42!L18 -> 0 | AT16: =기업43!L18 -> 0 | AU16: =기업44!L18 -> 5349569.7 | AV16: =기업45!L18 -> 5349569.7 | AW16: =기업46!L18 -> 5349569.7 | AX16: =기업47!L18 -> 5349569.7 | AY16: =기업48!L18 -> 5349569.7 | AZ16: =기업49!L18 -> 5349569.7 | BA16: =기업50!L18 -> 5349569.7 | BB16: =D16+E16+F16+G16+H16+I16+J16+K16+L16+M16+N16+O16+P16+Q16+R16+S16+T16+U16+V16+W16+X16+Y16+Z16+AA16+AB16+AC16+AD16+AE16+AF16+AG16+AH16+AI16+AJ16+AK16+AL16+AM16+AN16+AO16+AP16+AQ16+AR16+AS16+AT16+AU16+AV16+AW16+AX16+AY16+AZ16+BA16 -> 37446988
A17: 4 | B17: 부딪힘 | C17: 공학·관리적 조치 | D17: =기업01!L19 -> 0 | E17: =기업02!L19 -> 0 | F17: =기업03!L19 -> 0 | G17: =기업04!L19 -> 0 | H17: =기업05!L19 -> 0 | I17: =기업06!L19 -> 0 | J17: =기업07!L19 -> 0 | K17: =기업08!L19 -> 0 | L17: =기업09!L19 -> 0 | M17: =기업10!L19 -> 0 | N17: =기업11!L19 -> 0 | O17: =기업12!L19 -> 0 | P17: =기업13!L19 -> 0 | Q17: =기업14!L19 -> 0 | R17: =기업15!L19 -> 0 | S17: =기업16!L19 -> 0 | T17: =기업17!L19 -> 0 | U17: =기업18!L19 -> 0 | V17: =기업19!L19 -> 0 | W17: =기업20!L19 -> 0 | X17: =기업21!L19 -> 0 | Y17: =기업22!L19 -> 0 | Z17: =기업23!L19 -> 0 | AA17: =기업24!L19 -> 0 | AB17: =기업25!L19 -> 0 | AC17: =기업26!L19 -> 0 | AD17: =기업27!L19 -> 0 | AE17: =기업28!L19 -> 0 | AF17: =기업29!L19 -> 0 | AG17: =기업30!L19 -> 0 | AH17: =기업31!L19 -> 0 | AI17: =기업32!L19 -> 0 | AJ17: =기업33!L19 -> 0 | AK17: =기업34!L19 -> 0 | AL17: =기업35!L19 -> 0 | AM17: =기업36!L19 -> 0 | AN17: =기업37!L19 -> 0 | AO17: =기업38!L19 -> 0 | AP17: =기업39!L19 -> 0 | AQ17: =기업40!L19 -> 0 | AR17: =기업41!L19 -> 0 | AS17: =기업42!L19 -> 0 | AT17: =기업43!L19 -> 0 | AU17: =기업44!L19 -> 0 | AV17: =기업45!L19 -> 0 | AW17: =기업46!L19 -> 0 | AX17: =기업47!L19 -> 0 | AY17: =기업48!L19 -> 0 | AZ17: =기업49!L19 -> 0 | BA17: =기업50!L19 -> 0 | BB17: =D17+E17+F17+G17+H17+I17+J17+K17+L17+M17+N17+O17+P17+Q17+R17+S17+T17+U17+V17+W17+X17+Y17+Z17+AA17+AB17+AC17+AD17+AE17+AF17+AG17+AH17+AI17+AJ17+AK17+AL17+AM17+AN17+AO17+AP17+AQ17+AR17+AS17+AT17+AU17+AV17+AW17+AX17+AY17+AZ17+BA17 -> 0
C18: 개인보호구 지급 | D18: =기업01!L20 -> 0 | E18: =기업02!L20 -> 0 | F18: =기업03!L20 -> 0 | G18: =기업04!L20 -> 0 | H18: =기업05!L20 -> 0 | I18: =기업06!L20 -> 0 | J18: =기업07!L20 -> 0 | K18: =기업08!L20 -> 0 | L18: =기업09!L20 -> 0 | M18: =기업10!L20 -> 0 | N18: =기업11!L20 -> 0 | O18: =기업12!L20 -> 0 | P18: =기업13!L20 -> 0 | Q18: =기업14!L20 -> 0 | R18: =기업15!L20 -> 0 | S18: =기업16!L20 -> 0 | T18: =기업17!L20 -> 0 | U18: =기업18!L20 -> 0 | V18: =기업19!L20 -> 0 | W18: =기업20!L20 -> 0 | X18: =기업21!L20 -> 0 | Y18: =기업22!L20 -> 0 | Z18: =기업23!L20 -> 0 | AA18: =기업24!L20 -> 0 | AB18: =기업25!L20 -> 0 | AC18: =기업26!L20 -> 0 | AD18: =기업27!L20 -> 0 | AE18: =기업28!L20 -> 0 | AF18: =기업29!L20 -> 0 | AG18: =기업30!L20 -> 0 | AH18: =기업31!L20 -> 0 | AI18: =기업32!L20 -> 0 | AJ18: =기업33!L20 -> 0 | AK18: =기업34!L20 -> 0 | AL18: =기업35!L20 -> 0 | AM18: =기업36!L20 -> 0 | AN18: =기업37!L20 -> 3634176 | AO18: =기업38!L20 -> 3634176 | AP18: =기업39!L20 -> 3634176 | AQ18: =기업40!L20 -> 3634176 | AR18: =기업41!L20 -> 3634176 | AS18: =기업42!L20 -> 3634176 | AT18: =기업43!L20 -> 3634176 | AU18: =기업44!L20 -> 0 | AV18: =기업45!L20 -> 0 | AW18: =기업46!L20 -> 0 | AX18: =기업47!L20 -> 0 | AY18: =기업48!L20 -> 0 | AZ18: =기업49!L20 -> 0 | BA18: =기업50!L20 -> 0 | BB18: =D18+E18+F18+G18+H18+I18+J18+K18+L18+M18+N18+O18+P18+Q18+R18+S18+T18+U18+V18+W18+X18+Y18+Z18+AA18+AB18+AC18+AD18+AE18+AF18+AG18+AH18+AI18+AJ18+AK18+AL18+AM18+AN18+AO18+AP18+AQ18+AR18+AS18+AT18+AU18+AV18+AW18+AX18+AY18+AZ18+BA18 -> 25439232
C19: 행동 교정(교육) | D19: =기업01!L21 -> 0 | E19: =기업02!L21 -> 0 | F19: =기업03!L21 -> 0 | G19: =기업04!L21 -> 0 | H19: =기업05!L21 -> 0 | I19: =기업06!L21 -> 0 | J19: =기업07!L21 -> 0 | K19: =기업08!L21 -> 0 | L19: =기업09!L21 -> 0 | M19: =기업10!L21 -> 0 | N19: =기업11!L21 -> 0 | O19: =기업12!L21 -> 0 | P19: =기업13!L21 -> 0 | Q19: =기업14!L21 -> 0 | R19: =기업15!L21 -> 0 | S19: =기업16!L21 -> 0 | T19: =기업17!L21 -> 0 | U19: =기업18!L21 -> 0 | V19: =기업19!L21 -> 0 | W19: =기업20!L21 -> 0 | X19: =기업21!L21 -> 0 | Y19: =기업22!L21 -> 0 | Z19: =기업23!L21 -> 0 | AA19: =기업24!L21 -> 0 | AB19: =기업25!L21 -> 0 | AC19: =기업26!L21 -> 0 | AD19: =기업27!L21 -> 0 | AE19: =기업28!L21 -> 0 | AF19: =기업29!L21 -> 0 | AG19: =기업30!L21 -> 0 | AH19: =기업31!L21 -> 0 | AI19: =기업32!L21 -> 0 | AJ19: =기업33!L21 -> 0 | AK19: =기업34!L21 -> 0 | AL19: =기업35!L21 -> 0 | AM19: =기업36!L21 -> 0 | AN19: =기업37!L21 -> 0 | AO19: =기업38!L21 -> 0 | AP19: =기업39!L21 -> 0 | AQ19: =기업40!L21 -> 0 | AR19: =기업41!L21 -> 0 | AS19: =기업42!L21 -> 0 | AT19: =기업43!L21 -> 0 | AU19: =기업44!L21 -> 3634176 | AV19: =기업45!L21 -> 7268352 | AW19: =기업46!L21 -> 7268352 | AX19: =기업47!L21 -> 7268352 | AY19: =기업48!L21 -> 7268352 | AZ19: =기업49!L21 -> 7268352 | BA19: =기업50!L21 -> 3634176 | BB19: =D19+E19+F19+G19+H19+I19+J19+K19+L19+M19+N19+O19+P19+Q19+R19+S19+T19+U19+V19+W19+X19+Y19+Z19+AA19+AB19+AC19+AD19+AE19+AF19+AG19+AH19+AI19+AJ19+AK19+AL19+AM19+AN19+AO19+AP19+AQ19+AR19+AS19+AT19+AU19+AV19+AW19+AX19+AY19+AZ19+BA19 -> 43610112
A20: 5 | B20: 물체에 맞음 | C20: 공학·관리적 조치 | D20: =기업01!L22 -> 0 | E20: =기업02!L22 -> 16164137 | F20: =기업03!L22 -> 16164137 | G20: =기업04!L22 -> 16164137 | H20: =기업05!L22 -> 16164137 | I20: =기업06!L22 -> 16164137 | J20: =기업07!L22 -> 16164137 | K20: =기업08!L22 -> 16164137 | L20: =기업09!L22 -> 16164137 | M20: =기업10!L22 -> 32328274 | N20: =기업11!L22 -> 32328274 | O20: =기업12!L22 -> 32328274 | P20: =기업13!L22 -> 0 | Q20: =기업14!L22 -> 0 | R20: =기업15!L22 -> 0 | S20: =기업16!L22 -> 0 | T20: =기업17!L22 -> 0 | U20: =기업18!L22 -> 0 | V20: =기업19!L22 -> 0 | W20: =기업20!L22 -> 0 | X20: =기업21!L22 -> 0 | Y20: =기업22!L22 -> 0 | Z20: =기업23!L22 -> 0 | AA20: =기업24!L22 -> 0 | AB20: =기업25!L22 -> 0 | AC20: =기업26!L22 -> 0 | AD20: =기업27!L22 -> 0 | AE20: =기업28!L22 -> 0 | AF20: =기업29!L22 -> 0 | AG20: =기업30!L22 -> 0 | AH20: =기업31!L22 -> 0 | AI20: =기업32!L22 -> 0 | AJ20: =기업33!L22 -> 0 | AK20: =기업34!L22 -> 0 | AL20: =기업35!L22 -> 0 | AM20: =기업36!L22 -> 0 | AN20: =기업37!L22 -> 0 | AO20: =기업38!L22 -> 0 | AP20: =기업39!L22 -> 0 | AQ20: =기업40!L22 -> 0 | AR20: =기업41!L22 -> 0 | AS20: =기업42!L22 -> 0 | AT20: =기업43!L22 -> 0 | AU20: =기업44!L22 -> 0 | AV20: =기업45!L22 -> 0 | AW20: =기업46!L22 -> 0 | AX20: =기업47!L22 -> 0 | AY20: =기업48!L22 -> 0 | AZ20: =기업49!L22 -> 0 | BA20: =기업50!L22 -> 0 | BB20: =D20+E20+F20+G20+H20+I20+J20+K20+L20+M20+N20+O20+P20+Q20+R20+S20+T20+U20+V20+W20+X20+Y20+Z20+AA20+AB20+AC20+AD20+AE20+AF20+AG20+AH20+AI20+AJ20+AK20+AL20+AM20+AN20+AO20+AP20+AQ20+AR20+AS20+AT20+AU20+AV20+AW20+AX20+AY20+AZ20+BA20 -> 2.2629792e+08
C21: 개인보호구 지급 | D21: =기업01!L23 -> 0 | E21: =기업02!L23 -> 0 | F21: =기업03!L23 -> 0 | G21: =기업04!L23 -> 0 | H21: =기업05!L23 -> 0 | I21: =기업06!L23 -> 0 | J21: =기업07!L23 -> 0 | K21: =기업08!L23 -> 0 | L21: =기업09!L23 -> 0 | M21: =기업10!L23 -> 0 | N21: =기업11!L23 -> 0 | O21: =기업12!L23 -> 0 | P21: =기업13!L23 -> 0 | Q21: =기업14!L23 -> 0 | R21: =기업15!L23 -> 0 | S21: =기업16!L23 -> 0 | T21: =기업17!L23 -> 0 | U21: =기업18!L23 -> 0 | V21: =기업19!L23 -> 0 | W21: =기업20!L23 -> 0 | X21: =기업21!L23 -> 0 | Y21: =기업22!L23 -> 0 | Z21: =기업23!L23 -> 0 | AA21: =기업24!L23 -> 0 | AB21: =기업25!L23 -> 0 | AC21: =기업26!L23 -> 0 | AD21: =기업27!L23 -> 0 | AE21: =기업28!L23 -> 0 | AF21: =기업29!L23 -> 0 | AG21: =기업30!L23 -> 0 | AH21: =기업31!L23 -> 0 | AI21: =기업32!L23 -> 0 | AJ21: =기업33!L23 -> 0 | AK21: =기업34!L23 -> 0 | AL21: =기업35!L23 -> 0 | AM21: =기업36!L23 -> 0 | AN21: =기업37!L23 -> 0 | AO21: =기업38!L23 -> 0 | AP21: =기업39!L23 -> 0 | AQ21: =기업40!L23 -> 0 | AR21: =기업41!L23 -> 3463743.6 | AS21: =기업42!L23 -> 3463743.6 | AT21: =기업43!L23 -> 3463743.6 | AU21: =기업44!L23 -> 0 | AV21: =기업45!L23 -> 0 | AW21: =기업46!L23 -> 0 | AX21: =기업47!L23 -> 0 | AY21: =기업48!L23 -> 0 | AZ21: =기업49!L23 -> 0 | BA21: =기업50!L23 -> 0 | BB21: =D21+E21+F21+G21+H21+I21+J21+K21+L21+M21+N21+O21+P21+Q21+R21+S21+T21+U21+V21+W21+X21+Y21+Z21+AA21+AB21+AC21+AD21+AE21+AF21+AG21+AH21+AI21+AJ21+AK21+AL21+AM21+AN21+AO21+AP21+AQ21+AR21+AS21+AT21+AU21+AV21+AW21+AX21+AY21+AZ21+BA21 -> 10391231
C22: 행동 교정(교육) | D22: =기업01!L24 -> 0 | E22: =기업02!L24 -> 0 | F22: =기업03!L24 -> 0 | G22: =기업04!L24 -> 0 | H22: =기업05!L24 -> 0 | I22: =기업06!L24 -> 0 | J22: =기업07!L24 -> 0 | K22: =기업08!L24 -> 0 | L22: =기업09!L24 -> 0 | M22: =기업10!L24 -> 0 | N22: =기업11!L24 -> 0 | O22: =기업12!L24 -> 0 | P22: =기업13!L24 -> 0 | Q22: =기업14!L24 -> 0 | R22: =기업15!L24 -> 0 | S22: =기업16!L24 -> 0 | T22: =기업17!L24 -> 0 | U22: =기업18!L24 -> 0 | V22: =기업19!L24 -> 0 | W22: =기업20!L24 -> 0 | X22: =기업21!L24 -> 0 | Y22: =기업22!L24 -> 0 | Z22: =기업23!L24 -> 0 | AA22: =기업24!L24 -> 0 | AB22: =기업25!L24 -> 0 | AC22: =기업26!L24 -> 0 | AD22: =기업27!L24 -> 0 | AE22: =기업28!L24 -> 0 | AF22: =기업29!L24 -> 0 | AG22: =기업30!L24 -> 0 | AH22: =기업31!L24 -> 0 | AI22: =기업32!L24 -> 0 | AJ22: =기업33!L24 -> 0 | AK22: =기업34!L24 -> 0 | AL22: =기업35!L24 -> 0 | AM22: =기업36!L24 -> 0 | AN22: =기업37!L24 -> 0 | AO22: =기업38!L24 -> 0 | AP22: =기업39!L24 -> 0 | AQ22: =기업40!L24 -> 0 | AR22: =기업41!L24 -> 0 | AS22: =기업42!L24 -> 0 | AT22: =기업43!L24 -> 0 | AU22: =기업44!L24 -> 3463743.6 | AV22: =기업45!L24 -> 3463743.6 | AW22: =기업46!L24 -> 3463743.6 | AX22: =기업47!L24 -> 3463743.6 | AY22: =기업48!L24 -> 3463743.6 | AZ22: =기업49!L24 -> 3463743.6 | BA22: =기업50!L24 -> 3463743.6 | BB22: =D22+E22+F22+G22+H22+I22+J22+K22+L22+M22+N22+O22+P22+Q22+R22+S22+T22+U22+V22+W22+X22+Y22+Z22+AA22+AB22+AC22+AD22+AE22+AF22+AG22+AH22+AI22+AJ22+AK22+AL22+AM22+AN22+AO22+AP22+AQ22+AR22+AS22+AT22+AU22+AV22+AW22+AX22+AY22+AZ22+BA22 -> 24246205
A23: 6 | B23: 무너짐 | C23: 공학·관리적 조치 | D23: =기업01!L25 -> 0 | E23: =기업02!L25 -> 53035916 | F23: =기업03!L25 -> 53035916 | G23: =기업04!L25 -> 53035916 | H23: =기업05!L25 -> 53035916 | I23: =기업06!L25 -> 53035916 | J23: =기업07!L25 -> 53035916 | K23: =기업08!L25 -> 53035916 | L23: =기업09!L25 -> 53035916 | M23: =기업10!L25 -> 53035916 | N23: =기업11!L25 -> 53035916 | O23: =기업12!L25 -> 53035916 | P23: =기업13!L25 -> 53035916 | Q23: =기업14!L25 -> 53035916 | R23: =기업15!L25 -> 53035916 | S23: =기업16!L25 -> 53035916 | T23: =기업17!L25 -> 53035916 | U23: =기업18!L25 -> 53035916 | V23: =기업19!L25 -> 53035916 | W23: =기업20!L25 -> 53035916 | X23: =기업21!L25 -> 53035916 | Y23: =기업22!L25 -> 53035916 | Z23: =기업23!L25 -> 53035916 | AA23: =기업24!L25 -> 53035916 | AB23: =기업25!L25 -> 53035916 | AC23: =기업26!L25 -> 53035916 | AD23: =기업27!L25 -> 53035916 | AE23: =기업28!L25 -> 53035916 | AF23: =기업29!L25 -> 53035916 | AG23: =기업30!L25 -> 53035916 | AH23: =기업31!L25 -> 53035916 | AI23: =기업32!L25 -> 53035916 | AJ23: =기업33!L25 -> 53035916 | AK23: =기업34!L25 -> 53035916 | AL23: =기업35!L25 -> 53035916 | AM23: =기업36!L25 -> 53035916 | AN23: =기업37!L25 -> 0 | AO23: =기업38!L25 -> 0 | AP23: =기업39!L25 -> 0 | AQ23: =기업40!L25 -> 0 | AR23: =기업41!L25 -> 0 | AS23: =기업42!L25 -> 0 | AT23: =기업43!L25 -> 0 | AU23: =기업44!L25 -> 0 | AV23: =기업45!L25 -> 0 | AW23: =기업46!L25 -> 0 | AX23: =기업47!L25 -> 0 | AY23: =기업48!L25 -> 0 | AZ23: =기업49!L25 -> 0 | BA23: =기업50!L25 -> 0 | BB23: =D23+E23+F23+G23+H23+I23+J23+K23+L23+M23+N23+O23+P23+Q23+R23+S23+T23+U23+V23+W23+X23+Y23+Z23+AA23+AB23+AC23+AD23+AE23+AF23+AG23+AH23+AI23+AJ23+AK23+AL23+AM23+AN23+AO23+AP23+AQ23+AR23+AS23+AT23+AU23+AV23+AW23+AX23+AY23+AZ23+BA23 -> 1.8562571e+09
C24: 개인보호구 지급 | D24: =기업01!L26 -> 0 | E24: =기업02!L26 -> 0 | F24: =기업03!L26 -> 0 | G24: =기업04!L26 -> 0 | H24: =기업05!L26 -> 0 | I24: =기업06!L26 -> 0 | J24: =기업07!L26 -> 0 | K24: =기업08!L26 -> 0 | L24: =기업09!L26 -> 0 | M24: =기업10!L26 -> 0 | N24: =기업11!L26 -> 0 | O24: =기업12!L26 -> 0 | P24: =기업13!L26 -> 0 | Q24: =기업14!L26 -> 0 | R24: =기업15!L26 -> 0 | S24: =기업16!L26 -> 0 | T24: =기업17!L26 -> 0 | U24: =기업18!L26 -> 0 | V24: =기업19!L26 -> 0 | W24: =기업20!L26 -> 0 | X24: =기업21!L26 -> 0 | Y24: =기업22!L26 -> 0 | Z24: =기업23!L26 -> 0 | AA24: =기업24!L26 -> 0 | AB24: =기업25!L26 -> 0 | AC24: =기업26!L26 -> 0 | AD24: =기업27!L26 -> 0 | AE24: =기업28!L26 -> 0 | AF24: =기업29!L26 -> 0 | AG24: =기업30!L26 -> 0 | AH24: =기업31!L26 -> 0 | AI24: =기업32!L26 -> 0 | AJ24: =기업33!L26 -> 0 | AK24: =기업34!L26 -> 0 | AL24: =기업35!L26 -> 0 | AM24: =기업36!L26 -> 0 | AN24: =기업37!L26 -> 11364839 | AO24: =기업38!L26 -> 11364839 | AP24: =기업39!L26 -> 11364839 | AQ24: =기업40!L26 -> 11364839 | AR24: =기업41!L26 -> 11364839 | AS24: =기업42!L26 -> 11364839 | AT24: =기업43!L26 -> 11364839 | AU24: =기업44!L26 -> 0 | AV24: =기업45!L26 -> 0 | AW24: =기업46!L26 -> 0 | AX24: =기업47!L26 -> 0 | AY24: =기업48!L26 -> 0 | AZ24: =기업49!L26 -> 0 | BA24: =기업50!L26 -> 0 | BB24: =D24+E24+F24+G24+H24+I24+J24+K24+L24+M24+N24+O24+P24+Q24+R24+S24+T24+U24+V24+W24+X24+Y24+Z24+AA24+AB24+AC24+AD24+AE24+AF24+AG24+AH24+AI24+AJ24+AK24+AL24+AM24+AN24+AO24+AP24+AQ24+AR24+AS24+AT24+AU24+AV24+AW24+AX24+AY24+AZ24+BA24 -> 79553875
C25: 행동 교정(교육) | D25: =기업01!L27 -> 0 | E25: =기업02!L27 -> 0 | F25: =기업03!L27 -> 0 | G25: =기업04!L27 -> 0 | H25: =기업05!L27 -> 0 | I25: =기업06!L27 -> 0 | J25: =기업07!L27 -> 0 | K25: =기업08!L27 -> 0 | L25: =기업09!L27 -> 0 | M25: =기업10!L27 -> 0 | N25: =기업11!L27 -> 0 | O25: =기업12!L27 -> 0 | P25: =기업13!L27 -> 0 | Q25: =기업14!L27 -> 0 | R25: =기업15!L27 -> 0 | S25: =기업16!L27 -> 0 | T25: =기업17!L27 -> 0 | U25: =기업18!L27 -> 0 | V25: =기업19!L27 -> 0 | W25: =기업20!L27 -> 0 | X25: =기업21!L27 -> 0 | Y25: =기업22!L27 -> 0 | Z25: =기업23!L27 -> 0 | AA25: =기업24!L27 -> 0 | AB25: =기업25!L27 -> 0 | AC25: =기업26!L27 -> 0 | AD25: =기업27!L27 -> 0 | AE25: =기업28!L27 -> 0 | AF25: =기업29!L27 -> 0 | AG25: =기업30!L27 -> 0 | AH25: =기업31!L27 -> 0 | AI25: =기업32!L27 -> 0 | AJ25: =기업33!L27 -> 0 | AK25: =기업34!L27 -> 0 | AL25: =기업35!L27 -> 0 | AM25: =기업36!L27 -> 0 | AN25: =기업37!L27 -> 0 | AO25: =기업38!L27 -> 0 | AP25: =기업39!L27 -> 0 | AQ25: =기업40!L27 -> 0 | AR25: =기업41!L27 -> 0 | AS25: =기업42!L27 -> 0 | AT25: =기업43!L27 -> 0 | AU25: =기업44!L27 -> 11364839 | AV25: =기업45!L27 -> 11364839 | AW25: =기업46!L27 -> 11364839 | AX25: =기업47!L27 -> 11364839 | AY25: =기업48!L27 -> 11364839 | AZ25: =기업49!L27 -> 11364839 | BA25: =기업50!L27 -> 11364839 | BB25: =D25+E25+F25+G25+H25+I25+J25+K25+L25+M25+N25+O25+P25+Q25+R25+S25+T25+U25+V25+W25+X25+Y25+Z25+AA25+AB25+AC25+AD25+AE25+AF25+AG25+AH25+AI25+AJ25+AK25+AL25+AM25+AN25+AO25+AP25+AQ25+AR25+AS25+AT25+AU25+AV25+AW25+AX25+AY25+AZ25+BA25 -> 79553875
A26: 7 | B26: 끼임 | C26: 공학·관리적 조치 | D26: =기업01!L28 -> 0 | E26: =기업02!L28 -> 0 | F26: =기업03!L28 -> 0 | G26: =기업04!L28 -> 0 | H26: =기업05!L28 -> 0 | I26: =기업06!L28 -> 0 | J26: =기업07!L28 -> 0 | K26: =기업08!L28 -> 0 | L26: =기업09!L28 -> 0 | M26: =기업10!L28 -> 0 | N26: =기업11!L28 -> 0 | O26: =기업12!L28 -> 0 | P26: =기업13!L28 -> 0 | Q26: =기업14!L28 -> 0 | R26: =기업15!L28 -> 0 | S26: =기업16!L28 -> 0 | T26: =기업17!L28 -> 0 | U26: =기업18!L28 -> 0 | V26: =기업19!L28 -> 0 | W26: =기업20!L28 -> 0 | X26: =기업21!L28 -> 0 | Y26: =기업22!L28 -> 0 | Z26: =기업23!L28 -> 0 | AA26: =기업24!L28 -> 0 | AB26: =기업25!L28 -> 0 | AC26: =기업26!L28 -> 0 | AD26: =기업27!L28 -> 0 | AE26: =기업28!L28 -> 0 | AF26: =기업29!L28 -> 0 | AG26: =기업30!L28 -> 0 | AH26: =기업31!L28 -> 0 | AI26: =기업32!L28 -> 30144979 | AJ26: =기업33!L28 -> 30144979 | AK26: =기업34!L28 -> 30144979 | AL26: =기업35!L28 -> 30144979 | AM26: =기업36!L28 -> 30144979 | AN26: =기업37!L28 -> 0 | AO26: =기업38!L28 -> 0 | AP26: =기업39!L28 -> 0 | AQ26: =기업40!L28 -> 0 | AR26: =기업41!L28 -> 0 | AS26: =기업42!L28 -> 0 | AT26: =기업43!L28 -> 0 | AU26: =기업44!L28 -> 0 | AV26: =기업45!L28 -> 0 | AW26: =기업46!L28 -> 0 | AX26: =기업47!L28 -> 0 | AY26: =기업48!L28 -> 0 | AZ26: =기업49!L28 -> 0 | BA26: =기업50!L28 -> 0 | BB26: =D26+E26+F26+G26+H26+I26+J26+K26+L26+M26+N26+O26+P26+Q26+R26+S26+T26+U26+V26+W26+X26+Y26+Z26+AA26+AB26+AC26+AD26+AE26+AF26+AG26+AH26+AI26+AJ26+AK26+AL26+AM26+AN26+AO26+AP26+AQ26+AR26+AS26+AT26+AU26+AV26+AW26+AX26+AY26+AZ26+BA26 -> 150724896
C27: 개인보호구 지급 | D27: =기업01!L29 -> 0 | E27: =기업02!L29 -> 0 | F27: =기업03!L29 -> 0 | G27: =기업04!L29 -> 0 | H27: =기업05!L29 -> 0 | I27: =기업06!L29 -> 0 | J27: =기업07!L29 -> 0 | K27: =기업08!L29 -> 0 | L27: =기업09!L29 -> 0 | M27: =기업10!L29 -> 0 | N27: =기업11!L29 -> 0 | O27: =기업12!L29 -> 0 | P27: =기업13!L29 -> 0 | Q27: =기업14!L29 -> 0 | R27: =기업15!L29 -> 0 | S27: =기업16!L29 -> 0 | T27: =기업17!L29 -> 0 | U27: =기업18!L29 -> 0 | V27: =기업19!L29 -> 0 | W27: =기업20!L29 -> 0 | X27: =기업21!L29 -> 0 | Y27: =기업22!L29 -> 0 | Z27: =기업23!L29 -> 0 | AA27: =기업24!L29 -> 0 | AB27: =기업25!L29 -> 0 | AC27: =기업26!L29 -> 0 | AD27: =기업27!L29 -> 0 | AE27: =기업28!L29 -> 0 | AF27: =기업29!L29 -> 0 | AG27: =기업30!L29 -> 0 | AH27: =기업31!L29 -> 0 | AI27: =기업32!L29 -> 0 | AJ27: =기업33!L29 -> 0 | AK27: =기업34!L29 -> 0 | AL27: =기업35!L29 -> 0 | AM27: =기업36!L29 -> 0 | AN27: =기업37!L29 -> 3229819.2 | AO27: =기업38!L29 -> 3229819.2 | AP27: =기업39!L29 -> 3229819.2 | AQ27: =기업40!L29 -> 3229819.2 | AR27: =기업41!L29 -> 3229819.2 | AS27: =기업42!L29 -> 3229819.2 | AT27: =기업43!L29 -> 3229819.2 | AU27: =기업44!L29 -> 0 | AV27: =기업45!L29 -> 0 | AW27: =기업46!L29 -> 0 | AX27: =기업47!L29 -> 0 | AY27: =기업48!L29 -> 0 | AZ27: =기업49!L29 -> 0 | BA27: =기업50!L29 -> 0 | BB27: =D27+E27+F27+G27+H27+I27+J27+K27+L27+M27+N27+O27+P27+Q27+R27+S27+T27+U27+V27+W27+X27+Y27+Z27+AA27+AB27+AC27+AD27+AE27+AF27+AG27+AH27+AI27+AJ27+AK27+AL27+AM27+AN27+AO27+AP27+AQ27+AR27+AS27+AT27+AU27+AV27+AW27+AX27+AY27+AZ27+BA27 -> 22608734
C28: 행동 교정(교육) | D28: =기업01!L30 -> 0 | E28: =기업02!L30 -> 0 | F28: =기업03!L30 -> 0 | G28: =기업04!L30 -> 0 | H28: =기업05!L30 -> 0 | I28: =기업06!L30 -> 0 | J28: =기업07!L30 -> 0 | K28: =기업08!L30 -> 0 | L28: =기업09!L30 -> 0 | M28: =기업10!L30 -> 0 | N28: =기업11!L30 -> 0 | O28: =기업12!L30 -> 0 | P28: =기업13!L30 -> 0 | Q28: =기업14!L30 -> 0 | R28: =기업15!L30 -> 0 | S28: =기업16!L30 -> 0 | T28: =기업17!L30 -> 0 | U28: =기업18!L30 -> 0 | V28: =기업19!L30 -> 0 | W28: =기업20!L30 -> 0 | X28: =기업21!L30 -> 0 | Y28: =기업22!L30 -> 0 | Z28: =기업23!L30 -> 0 | AA28: =기업24!L30 -> 0 | AB28: =기업25!L30 -> 0 | AC28: =기업26!L30 -> 0 | AD28: =기업27!L30 -> 0 | AE28: =기업28!L30 -> 0 | AF28: =기업29!L30 -> 0 | AG28: =기업30!L30 -> 0 | AH28: =기업31!L30 -> 0 | AI28: =기업32!L30 -> 0 | AJ28: =기업33!L30 -> 0 | AK28: =기업34!L30 -> 0 | AL28: =기업35!L30 -> 0 | AM28: =기업36!L30 -> 0 | AN28: =기업37!L30 -> 0 | AO28: =기업38!L30 -> 0 | AP28: =기업39!L30 -> 0 | AQ28: =기업40!L30 -> 0 | AR28: =기업41!L30 -> 0 | AS28: =기업42!L30 -> 0 | AT28: =기업43!L30 -> 0 | AU28: =기업44!L30 -> 3229819.2 | AV28: =기업45!L30 -> 3229819.2 | AW28: =기업46!L30 -> 3229819.2 | AX28: =기업47!L30 -> 3229819.2 | AY28: =기업48!L30 -> 3229819.2 | AZ28: =기업49!L30 -> 3229819.2 | BA28: =기업50!L30 -> 3229819.2 | BB28: =D28+E28+F28+G28+H28+I28+J28+K28+L28+M28+N28+O28+P28+Q28+R28+S28+T28+U28+V28+W28+X28+Y28+Z28+AA28+AB28+AC28+AD28+AE28+AF28+AG28+AH28+AI28+AJ28+AK28+AL28+AM28+AN28+AO28+AP28+AQ28+AR28+AS28+AT28+AU28+AV28+AW28+AX28+AY28+AZ28+BA28 -> 22608734
A29: 8 | B29: 절단·베임·찔림 | C29: 공학·관리적 조치 | D29: =기업01!L31 -> 0 | E29: =기업02!L31 -> 0 | F29: =기업03!L31 -> 0 | G29: =기업04!L31 -> 0 | H29: =기업05!L31 -> 7786203.6 | I29: =기업06!L31 -> 7786203.6 | J29: =기업07!L31 -> 7786203.6 | K29: =기업08!L31 -> 7786203.6 | L29: =기업09!L31 -> 7786203.6 | M29: =기업10!L31 -> 7786203.6 | N29: =기업11!L31 -> 7786203.6 | O29: =기업12!L31 -> 7786203.6 | P29: =기업13!L31 -> 7786203.6 | Q29: =기업14!L31 -> 7786203.6 | R29: =기업15!L31 -> 7786203.6 | S29: =기업16!L31 -> 7786203.6 | T29: =기업17!L31 -> 7786203.6 | U29: =기업18!L31 -> 7786203.6 | V29: =기업19!L31 -> 7786203.6 | W29: =기업20!L31 -> 7786203.6 | X29: =기업21!L31 -> 7786203.6 | Y29: =기업22!L31 -> 7786203.6 | Z29: =기업23!L31 -> 7786203.6 | AA29: =기업24!L31 -> 7786203.6 | AB29: =기업25!L31 -> 7786203.6 | AC29: =기업26!L31 -> 7786203.6 | AD29: =기업27!L31 -> 7786203.6 | AE29: =기업28!L31 -> 7786203.6 | AF29: =기업29!L31 -> 7786203.6 | AG29: =기업30!L31 -> 7786203.6 | AH29: =기업31!L31 -> 7786203.6 | AI29: =기업32!L31 -> 7786203.6 | AJ29: =기업33!L31 -> 7786203.6 | AK29: =기업34!L31 -> 7786203.6 | AL29: =기업35!L31 -> 7786203.6 | AM29: =기업36!L31 -> 7786203.6 | AN29: =기업37!L31 -> 0 | AO29: =기업38!L31 -> 0 | AP29: =기업39!L31 -> 0 | AQ29: =기업40!L31 -> 0 | AR29: =기업41!L31 -> 0 | AS29: =기업42!L31 -> 0 | AT29: =기업43!L31 -> 0 | AU29: =기업44!L31 -> 0 | AV29: =기업45!L31 -> 0 | AW29: =기업46!L31 -> 0 | AX29: =기업47!L31 -> 0 | AY29: =기업48!L31 -> 0 | AZ29: =기업49!L31 -> 0 | BA29: =기업50!L31 -> 0 | BB29: =D29+E29+F29+G29+H29+I29+J29+K29+L29+M29+N29+O29+P29+Q29+R29+S29+T29+U29+V29+W29+X29+Y29+Z29+AA29+AB29+AC29+AD29+AE29+AF29+AG29+AH29+AI29+AJ29+AK29+AL29+AM29+AN29+AO29+AP29+AQ29+AR29+AS29+AT29+AU29+AV29+AW29+AX29+AY29+AZ29+BA29 -> 2.4915852e+08
C30: 개인보호구 지급 | D30: =기업01!L32 -> 0 | E30: =기업02!L32 -> 0 | F30: =기업03!L32 -> 0 | G30: =기업04!L32 -> 0 | H30: =기업05!L32 -> 0 | I30: =기업06!L32 -> 0 | J30: =기업07!L32 -> 0 | K30: =기업08!L32 -> 0 | L30: =기업09!L32 -> 0 | M30: =기업10!L32 -> 0 | N30: =기업11!L32 -> 0 | O30: =기업12!L32 -> 0 | P30: =기업13!L32 -> 0 | Q30: =기업14!L32 -> 0 | R30: =기업15!L32 -> 0 | S30: =기업16!L32 -> 0 | T30: =기업17!L32 -> 0 | U30: =기업18!L32 -> 0 | V30: =기업19!L32 -> 0 | W30: =기업20!L32 -> 0 | X30: =기업21!L32 -> 0 | Y30: =기업22!L32 -> 0 | Z30: =기업23!L32 -> 0 | AA30: =기업24!L32 -> 0 | AB30: =기업25!L32 -> 0 | AC30: =기업26!L32 -> 0 | AD30: =기업27!L32 -> 0 | AE30: =기업28!L32 -> 0 | AF30: =기업29!L32 -> 0 | AG30: =기업30!L32 -> 0 | AH30: =기업31!L32 -> 0 | AI30: =기업32!L32 -> 0 | AJ30: =기업33!L32 -> 0 | AK30: =기업34!L32 -> 0 | AL30: =기업35!L32 -> 0 | AM30: =기업36!L32 -> 0 | AN30: =기업37!L32 -> 1668472.2 | AO30: =기업38!L32 -> 1668472.2 | AP30: =기업39!L32 -> 1668472.2 | AQ30: =기업40!L32 -> 1668472.2 | AR30: =기업41!L32 -> 1668472.2 | AS30: =기업42!L32 -> 1668472.2 | AT30: =기업43!L32 -> 1668472.2 | AU30: =기업44!L32 -> 0 | AV30: =기업45!L32 -> 0 | AW30: =기업46!L32 -> 0 | AX30: =기업47!L32 -> 0 | AY30: =기업48!L32 -> 0 | AZ30: =기업49!L32 -> 0 | BA30: =기업50!L32 -> 0 | BB30: =D30+E30+F30+G30+H30+I30+J30+K30+L30+M30+N30+O30+P30+Q30+R30+S30+T30+U30+V30+W30+X30+Y30+Z30+AA30+AB30+AC30+AD30+AE30+AF30+AG30+AH30+AI30+AJ30+AK30+AL30+AM30+AN30+AO30+AP30+AQ30+AR30+AS30+AT30+AU30+AV30+AW30+AX30+AY30+AZ30+BA30 -> 11679305
C31: 행동 교정(교육) | D31: =기업01!L33 -> 0 | E31: =기업02!L33 -> 0 | F31: =기업03!L33 -> 0 | G31: =기업04!L33 -> 0 | H31: =기업05!L33 -> 0 | I31: =기업06!L33 -> 0 | J31: =기업07!L33 -> 0 | K31: =기업08!L33 -> 0 | L31: =기업09!L33 -> 0 | M31: =기업10!L33 -> 0 | N31: =기업11!L33 -> 0 | O31: =기업12!L33 -> 0 | P31: =기업13!L33 -> 0 | Q31: =기업14!L33 -> 0 | R31: =기업15!L33 -> 0 | S31: =기업16!L33 -> 0 | T31: =기업17!L33 -> 0 | U31: =기업18!L33 -> 0 | V31: =기업19!L33 -> 0 | W31: =기업20!L33 -> 0 | X31: =기업21!L33 -> 0 | Y31: =기업22!L33 -> 0 | Z31: =기업23!L33 -> 0 | AA31: =기업24!L33 -> 0 | AB31: =기업25!L33 -> 0 | AC31: =기업26!L33 -> 0 | AD31: =기업27!L33 -> 0 | AE31: =기업28!L33 -> 0 | AF31: =기업29!L33 -> 0 | AG31: =기업30!L33 -> 0 | AH31: =기업31!L33 -> 0 | AI31: =기업32!L33 -> 0 | AJ31: =기업33!L33 -> 0 | AK31: =기업34!L33 -> 0 | AL31: =기업35!L33 -> 0 | AM31: =기업36!L33 -> 0 | AN31: =기업37!L33 -> 0 | AO31: =기업38!L33 -> 0 | AP31: =기업39!L33 -> 0 | AQ31: =기업40!L33 -> 0 | AR31: =기업41!L33 -> 0 | AS31: =기업42!L33 -> 0 | AT31: =기업43!L33 -> 0 | AU31: =기업44!L33 -> 1668472.2 | AV31: =기업45!L33 -> 1668472.2 | AW31: =기업46!L33 -> 1668472.2 | AX31: =기업47!L33 -> 1668472.2 | AY31: =기업48!L33 -> 1668472.2 | AZ31: =기업49!L33 -> 1668472.2 | BA31: =기업50!L33 -> 1668472.2 | BB31: =D31+E31+F31+G31+H31+I31+J31+K31+L31+M31+N31+O31+P31+Q31+R31+S31+T31+U31+V31+W31+X31+Y31+Z31+AA31+AB31+AC31+AD31+AE31+AF31+AG31+AH31+AI31+AJ31+AK31+AL31+AM31+AN31+AO31+AP31+AQ31+AR31+AS31+AT31+AU31+AV31+AW31+AX31+AY31+AZ31+BA31 -> 11679305
A32: 9 | B32: 화재·폭발·파열 | C32: 공학·관리적 조치 | D32: =기업01!L34 -> 0 | E32: =기업02!L34 -> 0 | F32: =기업03!L34 -> 0 | G32: =기업04!L34 -> 0 | H32: =기업05!L34 -> 68685277 | I32: =기업06!L34 -> 68685277 | J32: =기업07!L34 -> 68685277 | K32: =기업08!L34 -> 68685277 | L32: =기업09!L34 -> 68685277 | M32: =기업10!L34 -> 68685277 | N32: =기업11!L34 -> 68685277 | O32: =기업12!L34 -> 68685277 | P32: =기업13!L34 -> 68685277 | Q32: =기업14!L34 -> 68685277 | R32: =기업15!L34 -> 68685277 | S32: =기업16!L34 -> 68685277 | T32: =기업17!L34 -> 68685277 | U32: =기업18!L34 -> 68685277 | V32: =기업19!L34 -> 68685277 | W32: =기업20!L34 -> 68685277 | X32: =기업21!L34 -> 68685277 | Y32: =기업22!L34 -> 68685277 | Z32: =기업23!L34 -> 68685277 | AA32: =기업24!L34 -> 68685277 | AB32: =기업25!L34 -> 68685277 | AC32: =기업26!L34 -> 68685277 | AD32: =기업27!L34 -> 68685277 | AE32: =기업28!L34 -> 68685277 | AF32: =기업29!L34 -> 68685277 | AG32: =기업30!L34 -> 68685277 | AH32: =기업31!L34 -> 68685277 | AI32: =기업32!L34 -> 68685277 | AJ32: =기업33!L34 -> 68685277 | AK32: =기업34!L34 -> 68685277 | AL32: =기업35!L34 -> 68685277 | AM32: =기업36!L34 -> 68685277 | AN32: =기업37!L34 -> 0 | AO32: =기업38!L34 -> 0 | AP32: =기업39!L34 -> 0 | AQ32: =기업40!L34 -> 0 | AR32: =기업41!L34 -> 0 | AS32: =기업42!L34 -> 0 | AT32: =기업43!L34 -> 0 | AU32: =기업44!L34 -> 0 | AV32: =기업45!L34 -> 0 | AW32: =기업46!L34 -> 0 | AX32: =기업47!L34 -> 0 | AY32: =기업48!L34 -> 0 | AZ32: =기업49!L34 -> 0 | BA32: =기업50!L34 -> 0 | BB32: =D32+E32+F32+G32+H32+I32+J32+K32+L32+M32+N32+O32+P32+Q32+R32+S32+T32+U32+V32+W32+X32+Y32+Z32+AA32+AB32+AC32+AD32+AE32+AF32+AG32+AH32+AI32+AJ32+AK32+AL32+AM32+AN32+AO32+AP32+AQ32+AR32+AS32+AT32+AU32+AV32+AW32+AX32+AY32+AZ32+BA32 -> 2.1979289e+09
C33: 개인보호구 지급 | D33: =기업01!L35 -> 0 | E33: =기업02!L35 -> 0 | F33: =기업03!L35 -> 0 | G33: =기업04!L35 -> 0 | H33: =기업05!L35 -> 0 | I33: =기업06!L35 -> 0 | J33: =기업07!L35 -> 0 | K33: =기업08!L35 -> 0 | L33: =기업09!L35 -> 0 | M33: =기업10!L35 -> 0 | N33: =기업11!L35 -> 0 | O33: =기업12!L35 -> 0 | P33: =기업13!L35 -> 0 | Q33: =기업14!L35 -> 0 | R33: =기업15!L35 -> 0 | S33: =기업16!L35 -> 0 | T33: =기업17!L35 -> 0 | U33: =기업18!L35 -> 0 | V33: =기업19!L35 -> 0 | W33: =기업20!L35 -> 0 | X33: =기업21!L35 -> 0 | Y33: =기업22!L35 -> 0 | Z33: =기업23!L35 -> 0 | AA33: =기업24!L35 -> 0 | AB33: =기업25!L35 -> 0 | AC33: =기업26!L35 -> 0 | AD33: =기업27!L35 -> 0 | AE33: =기업28!L35 -> 0 | AF33: =기업29!L35 -> 0 | AG33: =기업30!L35 -> 0 | AH33: =기업31!L35 -> 0 | AI33: =기업32!L35 -> 0 | AJ33: =기업33!L35 -> 0 | AK33: =기업34!L35 -> 0 | AL33: =기업35!L35 -> 0 | AM33: =기업36!L35 -> 0 | AN33: =기업37!L35 -> 0 | AO33: =기업38!L35 -> 0 | AP33: =기업39!L35 -> 0 | AQ33: =기업40!L35 -> 0 | AR33: =기업41!L35 -> 0 | AS33: =기업42!L35 -> 0 | AT33: =기업43!L35 -> 0 | AU33: =기업44!L35 -> 0 | AV33: =기업45!L35 -> 0 | AW33: =기업46!L35 -> 0 | AX33: =기업47!L35 -> 0 | AY33: =기업48!L35 -> 0 | AZ33: =기업49!L35 -> 0 | BA33: =기업50!L35 -> 0 | BB33: =D33+E33+F33+G33+H33+I33+J33+K33+L33+M33+N33+O33+P33+Q33+R33+S33+T33+U33+V33+W33+X33+Y33+Z33+AA33+AB33+AC33+AD33+AE33+AF33+AG33+AH33+AI33+AJ33+AK33+AL33+AM33+AN33+AO33+AP33+AQ33+AR33+AS33+AT33+AU33+AV33+AW33+AX33+AY33+AZ33+BA33 -> 0
C34: 행동 교정(교육) | D34: =기업01!L36 -> 0 | E34: =기업02!L36 -> 0 | F34: =기업03!L36 -> 0 | G34: =기업04!L36 -> 0 | H34: =기업05!L36 -> 0 | I34: =기업06!L36 -> 0 | J34: =기업07!L36 -> 0 | K34: =기업08!L36 -> 0 | L34: =기업09!L36 -> 0 | M34: =기업10!L36 -> 0 | N34: =기업11!L36 -> 0 | O34: =기업12!L36 -> 0 | P34: =기업13!L36 -> 0 | Q34: =기업14!L36 -> 0 | R34: =기업15!L36 -> 0 | S34: =기업16!L36 -> 0 | T34: =기업17!L36 -> 0 | U34: =기업18!L36 -> 0 | V34: =기업19!L36 -> 0 | W34: =기업20!L36 -> 0 | X34: =기업21!L36 -> 0 | Y34: =기업22!L36 -> 0 | Z34: =기업23!L36 -> 0 | AA34: =기업24!L36 -> 0 | AB34: =기업25!L36 -> 0 | AC34: =기업26!L36 -> 0 | AD34: =기업27!L36 -> 0 | AE34: =기업28!L36 -> 0 | AF34: =기업29!L36 -> 0 | AG34: =기업30!L36 -> 0 | AH34: =기업31!L36 -> 0 | AI34: =기업32!L36 -> 0 | AJ34: =기업33!L36 -> 0 | AK34: =기업34!L36 -> 0 | AL34: =기업35!L36 -> 0 | AM34: =기업36!L36 -> 0 | AN34: =기업37!L36 -> 0 | AO34: =기업38!L36 -> 0 | AP34: =기업39!L36 -> 0 | AQ34: =기업40!L36 -> 0 | AR34: =기업41!L36 -> 0 | AS34: =기업42!L36 -> 0 | AT34: =기업43!L36 -> 0 | AU34: =기업44!L36 -> 0 | AV34: =기업45!L36 -> 29436547 | AW34: =기업46!L36 -> 29436547 | AX34: =기업47!L36 -> 29436547 | AY34: =기업48!L36 -> 29436547 | AZ34: =기업49!L36 -> 29436547 | BA34: =기업50!L36 -> 29436547 | BB34: =D34+E34+F34+G34+H34+I34+J34+K34+L34+M34+N34+O34+P34+Q34+R34+S34+T34+U34+V34+W34+X34+Y34+Z34+AA34+AB34+AC34+AD34+AE34+AF34+AG34+AH34+AI34+AJ34+AK34+AL34+AM34+AN34+AO34+AP34+AQ34+AR34+AS34+AT34+AU34+AV34+AW34+AX34+AY34+AZ34+BA34 -> 1.7661928e+08
A35: 10 | B35: 교통사고 | C35: 공학·관리적 조치 | D35: =기업01!L37 -> 0 | E35: =기업02!L37 -> 0 | F35: =기업03!L37 -> 0 | G35: =기업04!L37 -> 0 | H35: =기업05!L37 -> 17806073 | I35: =기업06!L37 -> 17806073 | J35: =기업07!L37 -> 17806073 | K35: =기업08!L37 -> 17806073 | L35: =기업09!L37 -> 17806073 | M35: =기업10!L37 -> 17806073 | N35: =기업11!L37 -> 17806073 | O35: =기업12!L37 -> 17806073 | P35: =기업13!L37 -> 17806073 | Q35: =기업14!L37 -> 17806073 | R35: =기업15!L37 -> 17806073 | S35: =기업16!L37 -> 17806073 | T35: =기업17!L37 -> 17806073 | U35: =기업18!L37 -> 17806073 | V35: =기업19!L37 -> 17806073 | W35: =기업20!L37 -> 17806073 | X35: =기업21!L37 -> 17806073 | Y35: =기업22!L37 -> 17806073 | Z35: =기업23!L37 -> 17806073 | AA35: =기업24!L37 -> 17806073 | AB35: =기업25!L37 -> 17806073 | AC35: =기업26!L37 -> 17806073 | AD35: =기업27!L37 -> 17806073 | AE35: =기업28!L37 -> 17806073 | AF35: =기업29!L37 -> 17806073 | AG35: =기업30!L37 -> 17806073 | AH35: =기업31!L37 -> 17806073 | AI35: =기업32!L37 -> 35612146 | AJ35: =기업33!L37 -> 35612146 | AK35: =기업34!L37 -> 35612146 | AL35: =기업35!L37 -> 35612146 | AM35: =기업36!L37 -> 35612146 | AN35: =기업37!L37 -> 0 | AO35: =기업38!L37 -> 0 | AP35: =기업39!L37 -> 0 | AQ35: =기업40!L37 -> 0 | AR35: =기업41!L37 -> 0 | AS35: =기업42!L37 -> 0 | AT35: =기업43!L37 -> 0 | AU35: =기업44!L37 -> 0 | AV35: =기업45!L37 -> 0 | AW35: =기업46!L37 -> 0 | AX35: =기업47!L37 -> 0 | AY35: =기업48!L37 -> 0 | AZ35: =기업49!L37 -> 0 | BA35: =기업50!L37 -> 0 | BB35: =D35+E35+F35+G35+H35+I35+J35+K35+L35+M35+N35+O35+P35+Q35+R35+S35+T35+U35+V35+W35+X35+Y35+Z35+AA35+AB35+AC35+AD35+AE35+AF35+AG35+AH35+AI35+AJ35+AK35+AL35+AM35+AN35+AO35+AP35+AQ35+AR35+AS35+AT35+AU35+AV35+AW35+AX35+AY35+AZ35+BA35 -> 6.588247e+08
C36: 개인보호구 지급 | D36: =기업01!L38 -> 0 | E36: =기업02!L38 -> 0 | F36: =기업03!L38 -> 0 | G36: =기업04!L38 -> 0 | H36: =기업05!L38 -> 0 | I36: =기업06!L38 -> 0 | J36: =기업07!L38 -> 0 | K36: =기업08!L38 -> 0 | L36: =기업09!L38 -> 0 | M36: =기업10!L38 -> 0 | N36: =기업11!L38 -> 0 | O36: =기업12!L38 -> 0 | P36: =기업13!L38 -> 0 | Q36: =기업14!L38 -> 0 | R36: =기업15!L38 -> 0 | S36: =기업16!L38 -> 0 | T36: =기업17!L38 -> 0 | U36: =기업18!L38 -> 0 | V36: =기업19!L38 -> 0 | W36: =기업20!L38 -> 0 | X36: =기업21!L38 -> 0 | Y36: =기업22!L38 -> 0 | Z36: =기업23!L38 -> 0 | AA36: =기업24!L38 -> 0 | AB36: =기업25!L38 -> 0 | AC36: =기업26!L38 -> 0 | AD36: =기업27!L38 -> 0 | AE36: =기업28!L38 -> 0 | AF36: =기업29!L38 -> 0 | AG36: =기업30!L38 -> 0 | AH36: =기업31!L38 -> 0 | AI36: =기업32!L38 -> 0 | AJ36: =기업33!L38 -> 0 | AK36: =기업34!L38 -> 0 | AL36: =기업35!L38 -> 0 | AM36: =기업36!L38 -> 0 | AN36: =기업37!L38 -> 0 | AO36: =기업38!L38 -> 0 | AP36: =기업39!L38 -> 0 | AQ36: =기업40!L38 -> 0 | AR36: =기업41!L38 -> 0 | AS36: =기업42!L38 -> 0 | AT36: =기업43!L38 -> 0 | AU36: =기업44!L38 -> 0 | AV36: =기업45!L38 -> 0 | AW36: =기업46!L38 -> 0 | AX36: =기업47!L38 -> 0 | AY36: =기업48!L38 -> 0 | AZ36: =기업49!L38 -> 0 | BA36: =기업50!L38 -> 0 | BB36: =D36+E36+F36+G36+H36+I36+J36+K36+L36+M36+N36+O36+P36+Q36+R36+S36+T36+U36+V36+W36+X36+Y36+Z36+AA36+AB36+AC36+AD36+AE36+AF36+AG36+AH36+AI36+AJ36+AK36+AL36+AM36+AN36+AO36+AP36+AQ36+AR36+AS36+AT36+AU36+AV36+AW36+AX36+AY36+AZ36+BA36 -> 0
C37: 행동 교정(교육) | D37: =기업01!L39 -> 0 | E37: =기업02!L39 -> 0 | F37: =기업03!L39 -> 0 | G37: =기업04!L39 -> 0 | H37: =기업05!L39 -> 0 | I37: =기업06!L39 -> 0 | J37: =기업07!L39 -> 0 | K37: =기업08!L39 -> 0 | L37: =기업09!L39 -> 0 | M37: =기업10!L39 -> 0 | N37: =기업11!L39 -> 0 | O37: =기업12!L39 -> 0 | P37: =기업13!L39 -> 0 | Q37: =기업14!L39 -> 0 | R37: =기업15!L39 -> 0 | S37: =기업16!L39 -> 0 | T37: =기업17!L39 -> 0 | U37: =기업18!L39 -> 0 | V37: =기업19!L39 -> 0 | W37: =기업20!L39 -> 0 | X37: =기업21!L39 -> 0 | Y37: =기업22!L39 -> 0 | Z37: =기업23!L39 -> 0 | AA37: =기업24!L39 -> 0 | AB37: =기업25!L39 -> 0 | AC37: =기업26!L39 -> 0 | AD37: =기업27!L39 -> 0 | AE37: =기업28!L39 -> 0 | AF37: =기업29!L39 -> 0 | AG37: =기업30!L39 -> 0 | AH37: =기업31!L39 -> 0 | AI37: =기업32!L39 -> 0 | AJ37: =기업33!L39 -> 0 | AK37: =기업34!L39 -> 0 | AL37: =기업35!L39 -> 0 | AM37: =기업36!L39 -> 0 | AN37: =기업37!L39 -> 0 | AO37: =기업38!L39 -> 0 | AP37: =기업39!L39 -> 0 | AQ37: =기업40!L39 -> 0 | AR37: =기업41!L39 -> 0 | AS37: =기업42!L39 -> 0 | AT37: =기업43!L39 -> 0 | AU37: =기업44!L39 -> 0 | AV37: =기업45!L39 -> 0 | AW37: =기업46!L39 -> 0 | AX37: =기업47!L39 -> 0 | AY37: =기업48!L39 -> 0 | AZ37: =기업49!L39 -> 0 | BA37: =기업50!L39 -> 0 | BB37: =D37+E37+F37+G37+H37+I37+J37+K37+L37+M37+N37+O37+P37+Q37+R37+S37+T37+U37+V37+W37+X37+Y37+Z37+AA37+AB37+AC37+AD37+AE37+AF37+AG37+AH37+AI37+AJ37+AK37+AL37+AM37+AN37+AO37+AP37+AQ37+AR37+AS37+AT37+AU37+AV37+AW37+AX37+AY37+AZ37+BA37 -> 0
A38: 11 | B38: 무리한 동작 | C38: 공학·관리적 조치 | D38: =기업01!L40 -> 0 | E38: =기업02!L40 -> 0 | F38: =기업03!L40 -> 0 | G38: =기업04!L40 -> 0 | H38: =기업05!L40 -> 0 | I38: =기업06!L40 -> 0 | J38: =기업07!L40 -> 0 | K38: =기업08!L40 -> 0 | L38: =기업09!L40 -> 0 | M38: =기업10!L40 -> 0 | N38: =기업11!L40 -> 0 | O38: =기업12!L40 -> 0 | P38: =기업13!L40 -> 0 | Q38: =기업14!L40 -> 0 | R38: =기업15!L40 -> 0 | S38: =기업16!L40 -> 0 | T38: =기업17!L40 -> 0 | U38: =기업18!L40 -> 0 | V38: =기업19!L40 -> 0 | W38: =기업20!L40 -> 0 | X38: =기업21!L40 -> 0 | Y38: =기업22!L40 -> 0 | Z38: =기업23!L40 -> 0 | AA38: =기업24!L40 -> 0 | AB38: =기업25!L40 -> 0 | AC38: =기업26!L40 -> 0 | AD38: =기업27!L40 -> 0 | AE38: =기업28!L40 -> 0 | AF38: =기업29!L40 -> 0 | AG38: =기업30!L40 -> 0 | AH38: =기업31!L40 -> 0 | AI38: =기업32!L40 -> 0 | AJ38: =기업33!L40 -> 0 | AK38: =기업34!L40 -> 0 | AL38: =기업35!L40 -> 0 | AM38: =기업36!L40 -> 0 | AN38: =기업37!L40 -> 0 | AO38: =기업38!L40 -> 0 | AP38: =기업39!L40 -> 0 | AQ38: =기업40!L40 -> 0 | AR38: =기업41!L40 -> 0 | AS38: =기업42!L40 -> 0 | AT38: =기업43!L40 -> 0 | AU38: =기업44!L40 -> 0 | AV38: =기업45!L40 -> 0 | AW38: =기업46!L40 -> 0 | AX38: =기업47!L40 -> 0 | AY38: =기업48!L40 -> 0 | AZ38: =기업49!L40 -> 0 | BA38: =기업50!L40 -> 0 | BB38: =D38+E38+F38+G38+H38+I38+J38+K38+L38+M38+N38+O38+P38+Q38+R38+S38+T38+U38+V38+W38+X38+Y38+Z38+AA38+AB38+AC38+AD38+AE38+AF38+AG38+AH38+AI38+AJ38+AK38+AL38+AM38+AN38+AO38+AP38+AQ38+AR38+AS38+AT38+AU38+AV38+AW38+AX38+AY38+AZ38+BA38 -> 0
C39: 개인보호구 지급 | D39: =기업01!L41 -> 0 | E39: =기업02!L41 -> 0 | F39: =기업03!L41 -> 0 | G39: =기업04!L41 -> 0 | H39: =기업05!L41 -> 0 | I39: =기업06!L41 -> 0 | J39: =기업07!L41 -> 0 | K39: =기업08!L41 -> 0 | L39: =기업09!L41 -> 0 | M39: =기업10!L41 -> 0 | N39: =기업11!L41 -> 0 | O39: =기업12!L41 -> 0 | P39: =기업13!L41 -> 0 | Q39: =기업14!L41 -> 0 | R39: =기업15!L41 -> 0 | S39: =기업16!L41 -> 0 | T39: =기업17!L41 -> 0 | U39: =기업18!L41 -> 0 | V39: =기업19!L41 -> 0 | W39: =기업20!L41 -> 0 | X39: =기업21!L41 -> 0 | Y39: =기업22!L41 -> 0 | Z39: =기업23!L41 -> 0 | AA39: =기업24!L41 -> 0 | AB39: =기업25!L41 -> 0 | AC39: =기업26!L41 -> 0 | AD39: =기업27!L41 -> 0 | AE39: =기업28!L41 -> 0 | AF39: =기업29!L41 -> 0 | AG39: =기업30!L41 -> 0 | AH39: =기업31!L41 -> 0 | AI39: =기업32!L41 -> 0 | AJ39: =기업33!L41 -> 0 | AK39: =기업34!L41 -> 0 | AL39: =기업35!L41 -> 0 | AM39: =기업36!L41 -> 0 | AN39: =기업37!L41 -> 0 | AO39: =기업38!L41 -> 0 | AP39: =기업39!L41 -> 0 | AQ39: =기업40!L41 -> 0 | AR39: =기업41!L41 -> 0 | AS39: =기업42!L41 -> 0 | AT39: =기업43!L41 -> 0 | AU39: =기업44!L41 -> 0 | AV39: =기업45!L41 -> 0 | AW39: =기업46!L41 -> 0 | AX39: =기업47!L41 -> 0 | AY39: =기업48!L41 -> 0 | AZ39: =기업49!L41 -> 0 | BA39: =기업50!L41 -> 0 | BB39: =D39+E39+F39+G39+H39+I39+J39+K39+L39+M39+N39+O39+P39+Q39+R39+S39+T39+U39+V39+W39+X39+Y39+Z39+AA39+AB39+AC39+AD39+AE39+AF39+AG39+AH39+AI39+AJ39+AK39+AL39+AM39+AN39+AO39+AP39+AQ39+AR39+AS39+AT39+AU39+AV39+AW39+AX39+AY39+AZ39+BA39 -> 0
C40: 행동 교정(교육) | D40: =기업01!L42 -> 0 | E40: =기업02!L42 -> 0 | F40: =기업03!L42 -> 0 | G40: =기업04!L42 -> 0 | H40: =기업05!L42 -> 0 | I40: =기업06!L42 -> 0 | J40: =기업07!L42 -> 0 | K40: =기업08!L42 -> 0 | L40: =기업09!L42 -> 0 | M40: =기업10!L42 -> 0 | N40: =기업11!L42 -> 0 | O40: =기업12!L42 -> 0 | P40: =기업13!L42 -> 0 | Q40: =기업14!L42 -> 0 | R40: =기업15!L42 -> 0 | S40: =기업16!L42 -> 0 | T40: =기업17!L42 -> 0 | U40: =기업18!L42 -> 0 | V40: =기업19!L42 -> 0 | W40: =기업20!L42 -> 0 | X40: =기업21!L42 -> 0 | Y40: =기업22!L42 -> 0 | Z40: =기업23!L42 -> 0 | AA40: =기업24!L42 -> 0 | AB40: =기업25!L42 -> 0 | AC40: =기업26!L42 -> 0 | AD40: =기업27!L42 -> 0 | AE40: =기업28!L42 -> 0 | AF40: =기업29!L42 -> 0 | AG40: =기업30!L42 -> 0 | AH40: =기업31!L42 -> 0 | AI40: =기업32!L42 -> 0 | AJ40: =기업33!L42 -> 0 | AK40: =기업34!L42 -> 0 | AL40: =기업35!L42 -> 0 | AM40: =기업36!L42 -> 0 | AN40: =기업37!L42 -> 0 | AO40: =기업38!L42 -> 0 | AP40: =기업39!L42 -> 0 | AQ40: =기업40!L42 -> 0 | AR40: =기업41!L42 -> 0 | AS40: =기업42!L42 -> 0 | AT40: =기업43!L42 -> 0 | AU40: =기업44!L42 -> 0 | AV40: =기업45!L42 -> 1673767.2 | AW40: =기업46!L42 -> 1673767.2 | AX40: =기업47!L42 -> 1673767.2 | AY40: =기업48!L42 -> 1673767.2 | AZ40: =기업49!L42 -> 1673767.2 | BA40: =기업50!L42 -> 1673767.2 | BB40: =D40+E40+F40+G40+H40+I40+J40+K40+L40+M40+N40+O40+P40+Q40+R40+S40+T40+U40+V40+W40+X40+Y40+Z40+AA40+AB40+AC40+AD40+AE40+AF40+AG40+AH40+AI40+AJ40+AK40+AL40+AM40+AN40+AO40+AP40+AQ40+AR40+AS40+AT40+AU40+AV40+AW40+AX40+AY40+AZ40+BA40 -> 10042603
...

Sheet 기준데이터
A1: 기준데이터 – 수정 금지 (별첨 제1·2·7조)
A3: ▶ 위험요인별 사회비용 및 가중치
A4: No | B4: 위험요인 | C4: 사회비용(원) | D4: 공학·관리적 (0.70) | E4: 개인보호구 (0.15) | F4: 행동교정 (0.15)
A5: 1 | B5: 떨어짐 | C5: 37216793 | D5: 0.7 | E5: 0.15 | F5: 0.15
A6: 2 | B6: 넘어짐 | C6: 13387391 | D6: 0.7 | E6: 0.15 | F6: 0.15
A7: 3 | B7: 깔림·뒤집힘 | C7: 35663798 | D7: 0.7 | E7: 0.15 | F7: 0.15
A8: 4 | B8: 부딪힘 | C8: 24227840 | D8: 0.7 | E8: 0.15 | F8: 0.15
A9: 5 | B9: 물체에 맞음 | C9: 23091624 | D9: 0.7 | E9: 0.15 | F9: 0.15
A10: 6 | B10: 무너짐 | C10: 75765595 | D10: 0.7 | E10: 0.15 | F10: 0.15
A11: 7 | B11: 끼임 | C11: 21532128 | D11: 0.7 | E11: 0.15 | F11: 0.15
A12: 8 | B12: 절단·베임·찔림 | C12: 11123148 | D12: 0.7 | E12: 0.15 | F12: 0.15
A13: 9 | B13: 화재·폭발·파열 | C13: 98121824 | D13: 0.7 | E13: 0.15 | F13: 0.15
A14: 10 | B14: 교통사고 | C14: 25437247 | D14: 0.7 | E14: 0.15 | F14: 0.15
A15: 11 | B15: 무리한 동작 | C15: 11158448 | D15: 0.7 | E15: 0.15 | F15: 0.15
A16: 12 | B16: 감전 | C16: 61427885 | D16: 0.7 | E16: 0.15 | F16: 0.15
A17: 13 | B17: 기타 | C17: 19618150 | D17: 0.7 | E17: 0.15 | F17: 0.15

Sheet 기업01
